Workbook

Sheet rodada 1
B1: Parafusos | E1: Arruelas | H1: Alfinete | K1: Porta Agulhas | N1: Allis | Q1: Anatomica
A2: filename | B2: VP | C2: FP | D2: FN | E2: VP | F2: FP | G2: FN | H2: VP | I2: FP | J2: FN | K2: VP | L2: FP | M2: FN | N2: VP | O2: FP | P2: FN | Q2: VP | R2: FP | S2: FN
A3: Min_Chaos_Rodada_1_Imagem 01 | B3: 1 | C3: 0 | D3: 4 | E3: 0 | F3: 0 | G3: 5 | H3: 0 | I3: 0 | J3: 1 | K3: 2 | L3: 0 | M3: 0 | N3: 1 | O3: 0 | P3: 0 | Q3: 0 | R3: 0 | S3: 1
A4: Min_Chaos_Rodada_1_Imagem 02 | B4: 1 | C4: 0 | D4: 3 | E4: 0 | F4: 0 | G4: 5 | H4: 0 | I4: 0 | J4: 1 | K4: 2 | L4: 0 | M4: 0 | N4: 1 | O4: 0 | P4: 0 | Q4: 0 | R4: 0 | S4: 1
A5: Min_Chaos_Rodada_1_Imagem 03 | B5: 1 | C5: 0 | D5: 2 | E5: 0 | F5: 0 | G5: 5 | H5: 0 | I5: 0 | J5: 1 | K5: 2 | L5: 0 | M5: 0 | N5: 1 | O5: 0 | P5: 0 | Q5: 0 | R5: 0 | S5: 1
A6: Min_Chaos_Rodada_1_Imagem 04 | B6: 2 | C6: 0 | D6: 0 | E6: 0 | F6: 0 | G6: 5 | H6: 0 | I6: 0 | J6: 1 | K6: 2 | L6: 0 | M6: 0 | N6: 1 | O6: 0 | P6: 0 | Q6: 0 | R6: 0 | S6: 1
A7: Min_Chaos_Rodada_1_Imagem 05 | B7: 1 | C7: 0 | D7: 0 | E7: 0 | F7: 0 | G7: 5 | H7: 0 | I7: 0 | J7: 1 | K7: 2 | L7: 0 | M7: 0 | N7: 1 | O7: 0 | P7: 0 | Q7: 0 | R7: 0 | S7: 1
A8: Min_Chaos_Rodada_1_Imagem 06 | B8: 0 | C8: 0 | D8: 0 | E8: 1 | F8: 0 | G8: 4 | H8: 0 | I8: 0 | J8: 1 | K8: 2 | L8: 0 | M8: 0 | N8: 1 | O8: 0 | P8: 0 | Q8: 0 | R8: 0 | S8: 1
A9: Min_Chaos_Rodada_1_Imagem 07 | B9: 0 | C9: 0 | D9: 0 | E9: 2 | F9: 0 | G9: 2 | H9: 0 | I9: 0 | J9: 1 | K9: 2 | L9: 0 | M9: 0 | N9: 1 | O9: 0 | P9: 0 | Q9: 0 | R9: 0 | S9: 1
A10: Min_Chaos_Rodada_1_Imagem 08 | B10: 0 | C10: 0 | D10: 0 | E10: 1 | F10: 0 | G10: 2 | H10: 0 | I10: 0 | J10: 1 | K10: 2 | L10: 0 | M10: 0 | N10: 1 | O10: 0 | P10: 0 | Q10: 0 | R10: 0 | S10: 1
A11: Min_Chaos_Rodada_1_Imagem 09 | B11: 0 | C11: 0 | D11: 0 | E11: 0 | F11: 0 | G11: 2 | H11: 0 | I11: 0 | J11: 1 | K11: 2 | L11: 0 | M11: 0 | N11: 1 | O11: 0 | P11: 0 | Q11: 0 | R11: 0 | S11: 1
A12: Min_Chaos_Rodada_1_Imagem 10 | B12: 0 | C12: 0 | D12: 0 | E12: 1 | F12: 0 | G12: 0 | H12: 0 | I12: 0 | J12: 1 | K12: 2 | L12: 0 | M12: 0 | N12: 1 | O12: 0 | P12: 0 | Q12: 0 | R12: 0 | S12: 1
A13: Min_Chaos_Rodada_1_Imagem 11 | B13: 0 | C13: 0 | D13: 0 | E13: 0 | F13: 0 | G13: 0 | H13: 0 | I13: 0 | J13: 1 | K13: 2 | L13: 0 | M13: 0 | N13: 1 | O13: 0 | P13: 0 | Q13: 0 | R13: 0 | S13: 1
A14: Min_Chaos_Rodada_1_Imagem 12 | B14: 0 | C14: 0 | D14: 0 | E14: 0 | F14: 0 | G14: 0 | H14: 0 | I14: 0 | J14: 0 | K14: 2 | L14: 0 | M14: 0 | N14: 1 | O14: 0 | P14: 0 | Q14: 0 | R14: 0 | S14: 1
... A33: Min_Chaos_Rodada_1_Imagem 31 | B33: 1 | C33: 0 | D33: 4 | E33: 0 | F33: 0 | G33: 5 | H33: 1 | I33: 0 | J33: 0 | K33: 2 | L33: 0 | M33: 0 | N33: 1 | O33: 0 | P33: 0 | Q33: 0 | R33: 0 | S33: 1
A34: Total: | B34: =SUM(B3:B33) -> 10 | C34: =SUM(C3:C33) -> 0 | D34: =SUM(D3:D33) -> 20 | E34: =SUM(E3:E33) -> 8 | F34: =SUM(F3:F33) -> 0 | G34: =SUM(G3:G33) -> 72 | H34: =SUM(H3:H33) -> 11 | I34: =SUM(I3:I33) -> 0 | ... S34: =SUM(S3:S33) -> 28
A35: Precisão: | B35: =B34 / (B34 + C34) -> 1 | E35: =E34 / (E34 + F34) -> 1 | H35: =H34 / (H34 + I34) -> 1 | K35: =K34 / (K34 + L34) -> 0.90909091 | N35: =N34 / (N34 + O34) -> 0.95652174 | Q35: =Q34 / (Q34 + R34) -> 1
A36: Acurácia | B36: =B34 / (B34 + D34) -> 0.33333333 | E36: =E34 / (E34 + G34) -> 0.1 | H36: =H34 / (H34 + J34) -> 0.5 | K36: =K34 / (K34 + M34) -> 1 | N36: =N34 / (N34 + P34) -> 0.78571429 | Q36: =Q34 / (Q34 + S34) -> 0.066666667

Sheet rodada 2
B1: Parafusos | E1: Arruelas | H1: Alfinete | K1: Porta Agulhas | N1: Allis | Q1: Anatomica
A2: filename | B2: VP | C2: FP | D2: FN | E2: VP | F2: FP | G2: FN | H2: VP | I2: FP | J2: FN | K2: VP | L2: FP | M2: FN | N2: VP | O2: FP | P2: FN | Q2: VP | R2: FP | S2: FN
A3: Min_Chaos_Rodada_2_Imagem 01 | B3: 1 | C3: 0 | D3: 4 | E3: 0 | F3: 0 | G3: 5 | H3: 1 | I3: 0 | J3: 0 | K3: 2 | L3: 0 | M3: 0 | N3: 1 | O3: 0 | P3: 0 | Q3: 0 | R3: 0 | S3: 1
A4: Min_Chaos_Rodada_2_Imagem 02 | B4: 0 | C4: 0 | D4: 4 | E4: 0 | F4: 0 | G4: 5 | H4: 1 | I4: 0 | J4: 0 | K4: 2 | L4: 0 | M4: 0 | N4: 1 | O4: 0 | P4: 0 | Q4: 0 | R4: 0 | S4: 1
A5: Min_Chaos_Rodada_2_Imagem 03 | B5: 0 | C5: 0 | D5: 3 | E5: 0 | F5: 0 | G5: 5 | H5: 1 | I5: 0 | J5: 0 | K5: 2 | L5: 0 | M5: 0 | N5: 1 | O5: 0 | P5: 0 | Q5: 0 | R5: 0 | S5: 1
A6: Min_Chaos_Rodada_2_Imagem 04 | B6: 1 | C6: 0 | D6: 1 | E6: 0 | F6: 0 | G6: 5 | H6: 1 | I6: 0 | J6: 0 | K6: 2 | L6: 0 | M6: 0 | N6: 1 | O6: 0 | P6: 0 | Q6: 0 | R6: 0 | S6: 1
A7: Min_Chaos_Rodada_2_Imagem 05 | B7: 0 | C7: 0 | D7: 1 | E7: 0 | F7: 0 | G7: 5 | H7: 1 | I7: 0 | J7: 0 | K7: 2 | L7: 0 | M7: 0 | N7: 1 | O7: 0 | P7: 0 | Q7: 0 | R7: 0 | S7: 1
A8: Min_Chaos_Rodada_2_Imagem 06 | B8: 0 | C8: 0 | D8: 0 | E8: 0 | F8: 0 | G8: 5 | H8: 1 | I8: 0 | J8: 0 | K8: 2 | L8: 0 | M8: 0 | N8: 1 | O8: 0 | P8: 0 | Q8: 0 | R8: 0 | S8: 1
A9: Min_Chaos_Rodada_2_Imagem 07 | B9: 0 | C9: 0 | D9: 0 | E9: 0 | F9: 0 | G9: 4 | H9: 1 | I9: 0 | J9: 0 | K9: 2 | L9: 0 | M9: 0 | N9: 1 | O9: 0 | P9: 0 | Q9: 0 | R9: 0 | S9: 1
A10: Min_Chaos_Rodada_2_Imagem 08 | B10: 0 | C10: 0 | D10: 0 | E10: 1 | F10: 0 | G10: 2 | H10: 1 | I10: 0 | J10: 0 | K10: 2 | L10: 0 | M10: 0 | N10: 1 | O10: 0 | P10: 0 | Q10: 0 | R10: 0 | S10: 1
A11: Min_Chaos_Rodada_2_Imagem 09 | B11: 0 | C11: 0 | D11: 0 | E11: 0 | F11: 0 | G11: 2 | H11: 1 | I11: 0 | J11: 0 | K11: 2 | L11: 0 | M11: 0 | N11: 1 | O11: 0 | P11: 0 | Q11: 0 | R11: 0 | S11: 1
A12: Min_Chaos_Rodada_2_Imagem 10 | B12: 0 | C12: 0 | D12: 0 | E12: 0 | F12: 0 | G12: 1 | H12: 1 | I12: 0 | J12: 0 | K12: 2 | L12: 0 | M12: 0 | N12: 1 | O12: 0 | P12: 0 | Q12: 0 | R12: 0 | S12: 1
A13: Min_Chaos_Rodada_2_Imagem 11 | B13: 0 | C13: 0 | D13: 0 | E13: 0 | F13: 0 | G13: 0 | H13: 1 | I13: 0 | J13: 0 | K13: 2 | L13: 0 | M13: 0 | N13: 1 | O13: 0 | P13: 0 | Q13: 0 | R13: 0 | S13: 1
A14: Min_Chaos_Rodada_2_Imagem 12 | B14: 0 | C14: 0 | D14: 0 | E14: 0 | F14: 0 | G14: 0 | H14: 0 | I14: 0 | J14: 0 | K14: 2 | L14: 0 | M14: 0 | N14: 1 | O14: 0 | P14: 0 | Q14: 0 | R14: 0 | S14: 1
... A33: Min_Chaos_Rodada_2_Imagem 31 | B33: 1 | C33: 0 | D33: 4 | E33: 1 | F33: 0 | G33: 4 | H33: 0 | I33: 0 | J33: 1 | K33: 2 | L33: 0 | M33: 0 | N33: 1 | O33: 0 | P33: 0 | Q33: 0 | R33: 0 | S33: 1
A34: Total: | B34: =SUM(B3:B33) -> 5 | C34: =SUM(C3:C33) -> 0 | D34: =SUM(D3:D33) -> 25 | E34: =SUM(E3:E33) -> 12 | F34: =SUM(F3:F33) -> 0 | G34: =SUM(G3:G33) -> 68 | H34: =SUM(H3:H33) -> 20 | I34: =SUM(I3:I33) -> 0 | ... S34: =SUM(S3:S33) -> 29
A35: Precisão: | B35: =B34 / (B34 + C34) -> 1 | E35: =E34 / (E34 + F34) -> 1 | H35: =H34 / (H34 + I34) -> 1 | K35: =K34 / (K34 + L34) -> 1 | N35: =N34 / (N34 + O34) -> 1 | Q35: =Q34 / (Q34 + R34) -> 1
A36: Acurácia | B36: =B34 / (B34 + D34) -> 0.16666667 | E36: =E34 / (E34 + G34) -> 0.15 | H36: =H34 / (H34 + J34) -> 0.90909091 | K36: =K34 / (K34 + M34) -> 1 | N36: =N34 / (N34 + P34) -> 0.89285714 | Q36: =Q34 / (Q34 + S34) -> 0.033333333

Sheet rodada 3
B1: Parafusos | E1: Arruelas | H1: Alfinete | K1: Porta Agulhas | N1: Allis | Q1: Anatomica
A2: filename | B2: VP | C2: FP | D2: FN | E2: VP | F2: FP | G2: FN | H2: VP | I2: FP | J2: FN | K2: VP | L2: FP | M2: FN | N2: VP | O2: FP | P2: FN | Q2: VP | R2: FP | S2: FN
A3: Min_Chaos_Rodada_3_Imagem 01 | B3: 2 | C3: 0 | D3: 3 | E3: 0 | F3: 0 | G3: 5 | H3: 0 | I3: 0 | J3: 1 | K3: 1 | L3: 0 | M3: 1 | N3: 1 | O3: 0 | P3: 0 | Q3: 0 | R3: 0 | S3: 1
A4: Min_Chaos_Rodada_3_Imagem 02 | B4: 0 | C4: 0 | D4: 4 | E4: 0 | F4: 0 | G4: 5 | H4: 0 | I4: 0 | J4: 1 | K4: 2 | L4: 0 | M4: 0 | N4: 1 | O4: 0 | P4: 0 | Q4: 0 | R4: 0 | S4: 1
A5: Min_Chaos_Rodada_3_Imagem 03 | B5: 2 | C5: 0 | D5: 1 | E5: 0 | F5: 0 | G5: 5 | H5: 0 | I5: 0 | J5: 1 | K5: 1 | L5: 0 | M5: 1 | N5: 1 | O5: 0 | P5: 0 | Q5: 0 | R5: 0 | S5: 1
A6: Min_Chaos_Rodada_3_Imagem 04 | B6: 1 | C6: 0 | D6: 1 | E6: 0 | F6: 0 | G6: 5 | H6: 0 | I6: 0 | J6: 1 | K6: 1 | L6: 0 | M6: 1 | N6: 1 | O6: 0 | P6: 0 | Q6: 0 | R6: 0 | S6: 1
A7: Min_Chaos_Rodada_3_Imagem 05 | B7: 1 | C7: 0 | D7: 0 | E7: 0 | F7: 0 | G7: 5 | H7: 0 | I7: 0 | J7: 1 | K7: 1 | L7: 0 | M7: 1 | N7: 1 | O7: 0 | P7: 0 | Q7: 0 | R7: 0 | S7: 1
A8: Min_Chaos_Rodada_3_Imagem 06 | B8: 0 | C8: 0 | D8: 0 | E8: 0 | F8: 0 | G8: 5 | H8: 0 | I8: 0 | J8: 1 | K8: 1 | L8: 0 | M8: 1 | N8: 1 | O8: 0 | P8: 0 | Q8: 0 | R8: 0 | S8: 1
A9: Min_Chaos_Rodada_3_Imagem 07 | B9: 0 | C9: 0 | D9: 0 | E9: 2 | F9: 0 | G9: 2 | H9: 0 | I9: 0 | J9: 1 | K9: 1 | L9: 0 | M9: 1 | N9: 1 | O9: 0 | P9: 0 | Q9: 0 | R9: 0 | S9: 1
A10: Min_Chaos_Rodada_3_Imagem 08 | B10: 0 | C10: 0 | D10: 0 | E10: 1 | F10: 0 | G10: 2 | H10: 0 | I10: 0 | J10: 1 | K10: 1 | L10: 0 | M10: 1 | N10: 1 | O10: 0 | P10: 0 | Q10: 0 | R10: 0 | S10: 1
A11: Min_Chaos_Rodada_3_Imagem 09 | B11: 0 | C11: 0 | D11: 0 | E11: 0 | F11: 0 | G11: 2 | H11: 0 | I11: 0 | J11: 1 | K11: 2 | L11: 0 | M11: 0 | N11: 1 | O11: 0 | P11: 0 | Q11: 0 | R11: 0 | S11: 1
A12: Min_Chaos_Rodada_3_Imagem 10 | B12: 0 | C12: 0 | D12: 0 | E12: 0 | F12: 0 | G12: 1 | H12: 0 | I12: 0 | J12: 1 | K12: 1 | L12: 0 | M12: 1 | N12: 1 | O12: 0 | P12: 0 | Q12: 0 | R12: 0 | S12: 1
A13: Min_Chaos_Rodada_3_Imagem 11 | B13: 0 | C13: 0 | D13: 0 | E13: 0 | F13: 0 | G13: 0 | H13: 1 | I13: 0 | J13: 0 | K13: 2 | L13: 0 | M13: 0 | N13: 1 | O13: 0 | P13: 0 | Q13: 0 | R13: 0 | S13: 1
A14: Min_Chaos_Rodada_3_Imagem 12 | B14: 0 | C14: 0 | D14: 0 | E14: 0 | F14: 0 | G14: 0 | H14: 0 | I14: 0 | J14: 0 | K14: 2 | L14: 0 | M14: 0 | N14: 1 | O14: 0 | P14: 0 | Q14: 0 | R14: 0 | S14: 1
... A33: Min_Chaos_Rodada_3_Imagem 31 | B33: 1 | C33: 0 | D33: 4 | E33: 2 | F33: 0 | G33: 3 | H33: 0 | I33: 0 | J33: 1 | K33: 2 | L33: 0 | M33: 0 | N33: 1 | O33: 0 | P33: 0 | Q33: 0 | R33: 0 | S33: 1
A34: Total: | B34: =SUM(B3:B33) -> 10 | C34: =SUM(C3:C33) -> 0 | D34: =SUM(D3:D33) -> 20 | E34: =SUM(E3:E33) -> 20 | F34: =SUM(F3:F33) -> 0 | G34: =SUM(G3:G33) -> 60 | H34: =SUM(H3:H33) -> 11 | I34: =SUM(I3:I33) -> 0 | ... S34: =SUM(S3:S33) -> 28
A35: Precisão: | B35: =B34 / (B34 + C34) -> 1 | E35: =E34 / (E34 + F34) -> 1 | H35: =H34 / (H34 + I34) -> 1 | K35: =K34 / (K34 + L34) -> 1 | N35: =N34 / (N34 + O34) -> 1 | Q35: =Q34 / (Q34 + R34) -> 1
A36: Acurácia | B36: =B34 / (B34 + D34) -> 0.33333333 | E36: =E34 / (E34 + G34) -> 0.25 | H36: =H34 / (H34 + J34) -> 0.5 | K36: =K34 / (K34 + M34) -> 0.82 | N36: =N34 / (N34 + P34) -> 1 | Q36: =Q34 / (Q34 + S34) -> 0.066666667

Sheet rodada 4
B1: Parafusos | E1: Arruelas | H1: Alfinete | K1: Porta Agulhas | N1: Allis | Q1: Anatomica
A2: filename | B2: VP | C2: FP | D2: FN | E2: VP | F2: FP | G2: FN | H2: VP | I2: FP | J2: FN | K2: VP | L2: FP | M2: FN | N2: VP | O2: FP | P2: FN | Q2: VP | R2: FP | S2: FN
A3: Min_Chaos_Rodada_4_Imagem 01 | B3: 2 | C3: 0 | D3: 3 | E3: 2 | F3: 0 | G3: 3 | H3: 0 | I3: 0 | J3: 1 | K3: 1 | L3: 0 | M3: 1 | N3: 1 | O3: 0 | P3: 0 | Q3: 0 | R3: 0 | S3: 1
A4: Min_Chaos_Rodada_4_Imagem 02 | B4: 2 | C4: 0 | D4: 2 | E4: 2 | F4: 0 | G4: 3 | H4: 0 | I4: 0 | J4: 1 | K4: 2 | L4: 0 | M4: 0 | N4: 1 | O4: 0 | P4: 0 | Q4: 0 | R4: 0 | S4: 1
A5: Min_Chaos_Rodada_4_Imagem 03 | B5: 1 | C5: 0 | D5: 2 | E5: 2 | F5: 0 | G5: 3 | H5: 0 | I5: 0 | J5: 1 | K5: 1 | L5: 0 | M5: 1 | N5: 1 | O5: 0 | P5: 0 | Q5: 0 | R5: 0 | S5: 1
A6: Min_Chaos_Rodada_4_Imagem 04 | B6: 2 | C6: 0 | D6: 0 | E6: 2 | F6: 0 | G6: 3 | H6: 1 | I6: 0 | J6: 0 | K6: 2 | L6: 0 | M6: 0 | N6: 1 | O6: 0 | P6: 0 | Q6: 0 | R6: 0 | S6: 1
A7: Min_Chaos_Rodada_4_Imagem 05 | B7: 1 | C7: 0 | D7: 0 | E7: 2 | F7: 0 | G7: 3 | H7: 1 | I7: 0 | J7: 0 | K7: 2 | L7: 0 | M7: 0 | N7: 1 | O7: 0 | P7: 0 | Q7: 0 | R7: 0 | S7: 1
A8: Min_Chaos_Rodada_4_Imagem 06 | B8: 0 | C8: 0 | D8: 0 | E8: 2 | F8: 0 | G8: 3 | H8: 1 | I8: 0 | J8: 0 | K8: 1 | L8: 0 | M8: 1 | N8: 1 | O8: 0 | P8: 0 | Q8: 0 | R8: 0 | S8: 1
A9: Min_Chaos_Rodada_4_Imagem 07 | B9: 0 | C9: 0 | D9: 0 | E9: 1 | F9: 0 | G9: 3 | H9: 1 | I9: 0 | J9: 0 | K9: 2 | L9: 0 | M9: 0 | N9: 1 | O9: 0 | P9: 0 | Q9: 0 | R9: 0 | S9: 1
A10: Min_Chaos_Rodada_4_Imagem 08 | B10: 0 | C10: 0 | D10: 0 | E10: 1 | F10: 0 | G10: 2 | H10: 1 | I10: 0 | J10: 0 | K10: 2 | L10: 0 | M10: 0 | N10: 1 | O10: 0 | P10: 0 | Q10: 0 | R10: 0 | S10: 1
A11: Min_Chaos_Rodada_4_Imagem 09 | B11: 0 | C11: 0 | D11: 0 | E11: 1 | F11: 0 | G11: 1 | H11: 1 | I11: 0 | J11: 0 | K11: 1 | L11: 0 | M11: 1 | N11: 1 | O11: 0 | P11: 0 | Q11: 0 | R11: 0 | S11: 1
A12: Min_Chaos_Rodada_4_Imagem 10 | B12: 0 | C12: 0 | D12: 0 | E12: 1 | F12: 0 | G12: 0 | H12: 1 | I12: 0 | J12: 0 | K12: 1 | L12: 0 | M12: 1 | N12: 1 | O12: 0 | P12: 0 | Q12: 0 | R12: 0 | S12: 1
A13: Min_Chaos_Rodada_4_Imagem 11 | B13: 0 | C13: 0 | D13: 0 | E13: 0 | F13: 0 | G13: 0 | H13: 1 | I13: 0 | J13: 0 | K13: 1 | L13: 0 | M13: 1 | N13: 1 | O13: 0 | P13: 0 | Q13: 0 | R13: 0 | S13: 1
A14: Min_Chaos_Rodada_4_Imagem 12 | B14: 0 | C14: 0 | D14: 0 | E14: 0 | F14: 0 | G14: 0 | H14: 0 | I14: 0 | J14: 0 | K14: 2 | L14: 0 | M14: 0 | N14: 1 | O14: 0 | P14: 0 | Q14: 0 | R14: 0 | S14: 1
... A33: Min_Chaos_Rodada_4_Imagem 31 | B33: 0 | C33: 0 | D33: 5 | E33: 1 | F33: 0 | G33: 4 | H33: 1 | I33: 0 | J33: 0 | K33: 1 | L33: 0 | M33: 1 | N33: 1 | O33: 0 | P33: 0 | Q33: 0 | R33: 0 | S33: 1
A34: Total: | B34: =SUM(B3:B33) -> 8 | C34: =SUM(C3:C33) -> 0 | D34: =SUM(D3:D33) -> 22 | E34: =SUM(E3:E33) -> 27 | F34: =SUM(F3:F33) -> 0 | G34: =SUM(G3:G33) -> 53 | H34: =SUM(H3:H33) -> 18 | I34: =SUM(I3:I33) -> 0 | ... S34: =SUM(S3:S33) -> 29
A35: Precisão: | B35: =B34 / (B34 + C34) -> 1 | E35: =E34 / (E34 + F34) -> 1 | H35: =H34 / (H34 + I34) -> 1 | K35: =K34 / (K34 + L34) -> 1 | N35: =N34 / (N34 + O34) -> 1 | Q35: =Q34 / (Q34 + R34) -> 1
A36: Acurácia | B36: =B34 / (B34 + D34) -> 0.26666667 | E36: =E34 / (E34 + G34) -> 0.3375 | H36: =H34 / (H34 + J34) -> 0.81818182 | K36: =K34 / (K34 + M34) -> 0.64 | N36: =N34 / (N34 + P34) -> 1 | Q36: =Q34 / (Q34 + S34) -> 0.033333333

Sheet rodada 5
B1: Parafusos | E1: Arruelas | H1: Alfinete | K1: Porta Agulhas | N1: Allis | Q1: Anatomica
A2: filename | B2: VP | C2: FP | D2: FN | E2: VP | F2: FP | G2: FN | H2: VP | I2: FP | J2: FN | K2: VP | L2: FP | M2: FN | N2: VP | O2: FP | P2: FN | Q2: VP | R2: FP | S2: FN
A3: Min_Chaos_Rodada_5_Imagem 01 | B3: 1 | C3: 0 | D3: 4 | E3: 0 | F3: 0 | G3: 5 | H3: 1 | I3: 0 | J3: 0 | K3: 1 | L3: 0 | M3: 1 | N3: 1 | O3: 0 | P3: 0 | Q3: 0 | R3: 0 | S3: 1
A4: Min_Chaos_Rodada_5_Imagem 02 | B4: 1 | C4: 0 | D4: 3 | E4: 0 | F4: 0 | G4: 5 | H4: 1 | I4: 0 | J4: 0 | K4: 1 | L4: 0 | M4: 1 | N4: 1 | O4: 0 | P4: 0 | Q4: 0 | R4: 0 | S4: 1
A5: Min_Chaos_Rodada_5_Imagem 03 | B5: 1 | C5: 0 | D5: 2 | E5: 0 | F5: 0 | G5: 5 | H5: 1 | I5: 0 | J5: 0 | K5: 1 | L5: 0 | M5: 1 | N5: 1 | O5: 0 | P5: 0 | Q5: 0 | R5: 0 | S5: 1
A6: Min_Chaos_Rodada_5_Imagem 04 | B6: 1 | C6: 0 | D6: 1 | E6: 0 | F6: 0 | G6: 5 | H6: 1 | I6: 0 | J6: 0 | K6: 1 | L6: 0 | M6: 1 | N6: 1 | O6: 0 | P6: 0 | Q6: 0 | R6: 0 | S6: 1
A7: Min_Chaos_Rodada_5_Imagem 05 | B7: 1 | C7: 0 | D7: 0 | E7: 0 | F7: 0 | G7: 5 | H7: 1 | I7: 0 | J7: 0 | K7: 1 | L7: 0 | M7: 1 | N7: 1 | O7: 0 | P7: 0 | Q7: 0 | R7: 0 | S7: 1
A8: Min_Chaos_Rodada_5_Imagem 06 | B8: 0 | C8: 0 | D8: 0 | E8: 0 | F8: 0 | G8: 5 | H8: 1 | I8: 0 | J8: 0 | K8: 1 | L8: 0 | M8: 1 | N8: 1 | O8: 0 | P8: 0 | Q8: 0 | R8: 0 | S8: 1
A9: Min_Chaos_Rodada_5_Imagem 07 | B9: 0 | C9: 0 | D9: 0 | E9: 0 | F9: 0 | G9: 4 | H9: 1 | I9: 0 | J9: 0 | K9: 1 | L9: 0 | M9: 1 | N9: 1 | O9: 0 | P9: 0 | Q9: 0 | R9: 0 | S9: 1
A10: Min_Chaos_Rodada_5_Imagem 08 | B10: 0 | C10: 0 | D10: 0 | E10: 0 | F10: 0 | G10: 3 | H10: 1 | I10: 0 | J10: 0 | K10: 1 | L10: 0 | M10: 1 | N10: 1 | O10: 0 | P10: 0 | Q10: 0 | R10: 0 | S10: 1
A11: Min_Chaos_Rodada_5_Imagem 09 | B11: 0 | C11: 0 | D11: 0 | E11: 0 | F11: 0 | G11: 2 | H11: 1 | I11: 0 | J11: 0 | K11: 1 | L11: 0 | M11: 1 | N11: 1 | O11: 0 | P11: 0 | Q11: 0 | R11: 0 | S11: 1
A12: Min_Chaos_Rodada_5_Imagem 10 | B12: 0 | C12: 0 | D12: 0 | E12: 0 | F12: 0 | G12: 1 | H12: 1 | I12: 0 | J12: 0 | K12: 1 | L12: 0 | M12: 1 | N12: 1 | O12: 0 | P12: 0 | Q12: 0 | R12: 0 | S12: 1
A13: Min_Chaos_Rodada_5_Imagem 11 | B13: 0 | C13: 0 | D13: 0 | E13: 0 | F13: 0 | G13: 0 | H13: 1 | I13: 0 | J13: 0 | K13: 1 | L13: 0 | M13: 1 | N13: 1 | O13: 0 | P13: 0 | Q13: 0 | R13: 0 | S13: 1
A14: Min_Chaos_Rodada_5_Imagem 12 | B14: 0 | C14: 0 | D14: 0 | E14: 0 | F14: 0 | G14: 0 | H14: 0 | I14: 0 | J14: 0 | K14: 1 | L14: 0 | M14: 1 | N14: 1 | O14: 0 | P14: 0 | Q14: 0 | R14: 0 | S14: 1
... A33: Min_Chaos_Rodada_5_Imagem 31 | B33: 2 | C33: 0 | D33: 3 | E33: 2 | F33: 0 | G33: 3 | H33: 0 | I33: 0 | J33: 1 | K33: 1 | L33: 0 | M33: 1 | N33: 1 | O33: 0 | P33: 0 | Q33: 0 | R33: 1 | S33: 1
A34: Total: | B34: =SUM(B3:B33) -> 12 | C34: =SUM(C3:C33) -> 0 | D34: =SUM(D3:D33) -> 18 | E34: =SUM(E3:E33) -> 17 | F34: =SUM(F3:F33) -> 0 | G34: =SUM(G3:G33) -> 63 | H34: =SUM(H3:H33) -> 18 | I34: =SUM(I3:I33) -> 0 | ... S34: =SUM(S3:S33) -> 28
A35: Precisão: | B35: =B34 / (B34 + C34) -> 1 | E35: =E34 / (E34 + F34) -> 1 | H35: =H34 / (H34 + I34) -> 1 | K35: =K34 / (K34 + L34) -> 0.97222222 | N35: =N34 / (N34 + O34) -> 1 | Q35: =Q34 / (Q34 + R34) -> 0.4
A36: Acurácia | B36: =B34 / (B34 + D34) -> 0.4 | E36: =E34 / (E34 + G34) -> 0.2125 | H36: =H34 / (H34 + J34) -> 0.81818182 | K36: =K34 / (K34 + M34) -> 0.7 | N36: =N34 / (N34 + P34) -> 0.96428571 | Q36: =Q34 / (Q34 + S34) -> 0.066666667

Sheet rodada 6
B1: Parafusos | E1: Arruelas | H1: Alfinete | K1: Porta Agulhas | N1: Allis | Q1: Anatomica
A2: filename | B2: VP | C2: FP | D2: FN | E2: VP | F2: FP | G2: FN | H2: VP | I2: FP | J2: FN | K2: VP | L2: FP | M2: FN | N2: VP | O2: FP | P2: FN | Q2: VP | R2: FP | S2: FN
A3: Min_Chaos_Rodada_6_Imagem 01 | B3: 2 | C3: 0 | D3: 3 | E3: 2 | F3: 0 | G3: 3 | H3: 0 | I3: 0 | J3: 1 | K3: 1 | L3: 0 | M3: 1 | N3: 1 | O3: 0 | P3: 0 | Q3: 0 | R3: 1 | S3: 1
A4: Min_Chaos_Rodada_6_Imagem 02 | B4: 1 | C4: 0 | D4: 3 | E4: 1 | F4: 0 | G4: 4 | H4: 0 | I4: 0 | J4: 1 | K4: 1 | L4: 0 | M4: 1 | N4: 1 | O4: 0 | P4: 0 | Q4: 0 | R4: 1 | S4: 1
A5: Min_Chaos_Rodada_6_Imagem 03 | B5: 2 | C5: 0 | D5: 1 | E5: 2 | F5: 0 | G5: 3 | H5: 0 | I5: 0 | J5: 1 | K5: 1 | L5: 0 | M5: 1 | N5: 1 | O5: 0 | P5: 0 | Q5: 0 | R5: 1 | S5: 1
A6: Min_Chaos_Rodada_6_Imagem 04 | B6: 1 | C6: 0 | D6: 1 | E6: 2 | F6: 0 | G6: 3 | H6: 0 | I6: 0 | J6: 1 | K6: 1 | L6: 0 | M6: 1 | N6: 1 | O6: 0 | P6: 0 | Q6: 0 | R6: 1 | S6: 1
A7: Min_Chaos_Rodada_6_Imagem 05 | B7: 1 | C7: 0 | D7: 0 | E7: 2 | F7: 0 | G7: 3 | H7: 0 | I7: 0 | J7: 1 | K7: 1 | L7: 0 | M7: 1 | N7: 1 | O7: 0 | P7: 0 | Q7: 0 | R7: 1 | S7: 1
A8: Min_Chaos_Rodada_6_Imagem 06 | B8: 0 | C8: 0 | D8: 0 | E8: 2 | F8: 0 | G8: 3 | H8: 0 | I8: 0 | J8: 1 | K8: 1 | L8: 0 | M8: 1 | N8: 1 | O8: 0 | P8: 0 | Q8: 0 | R8: 1 | S8: 1
A9: Min_Chaos_Rodada_6_Imagem 07 | B9: 0 | C9: 0 | D9: 0 | E9: 2 | F9: 0 | G9: 2 | H9: 0 | I9: 0 | J9: 1 | K9: 1 | L9: 0 | M9: 1 | N9: 1 | O9: 0 | P9: 0 | Q9: 0 | R9: 1 | S9: 1
A10: Min_Chaos_Rodada_6_Imagem 08 | B10: 0 | C10: 0 | D10: 0 | E10: 1 | F10: 0 | G10: 2 | H10: 1 | I10: 0 | J10: 0 | K10: 1 | L10: 0 | M10: 1 | N10: 1 | O10: 0 | P10: 0 | Q10: 0 | R10: 1 | S10: 1
A11: Min_Chaos_Rodada_6_Imagem 09 | B11: 0 | C11: 0 | D11: 0 | E11: 0 | F11: 0 | G11: 2 | H11: 0 | I11: 0 | J11: 1 | K11: 1 | L11: 0 | M11: 1 | N11: 1 | O11: 0 | P11: 0 | Q11: 0 | R11: 1 | S11: 1
A12: Min_Chaos_Rodada_6_Imagem 10 | B12: 0 | C12: 0 | D12: 0 | E12: 1 | F12: 0 | G12: 0 | H12: 0 | I12: 0 | J12: 1 | K12: 1 | L12: 0 | M12: 1 | N12: 1 | O12: 0 | P12: 0 | Q12: 0 | R12: 1 | S12: 1
A13: Min_Chaos_Rodada_6_Imagem 11 | B13: 0 | C13: 0 | D13: 0 | E13: 0 | F13: 0 | G13: 0 | H13: 1 | I13: 0 | J13: 0 | K13: 1 | L13: 0 | M13: 1 | N13: 1 | O13: 0 | P13: 0 | Q13: 0 | R13: 1 | S13: 1
A14: Min_Chaos_Rodada_6_Imagem 12 | B14: 0 | C14: 0 | D14: 0 | E14: 0 | F14: 0 | G14: 0 | H14: 0 | I14: 0 | J14: 0 | K14: 2 | L14: 0 | M14: 0 | N14: 1 | O14: 0 | P14: 0 | Q14: 0 | R14: 0 | S14: 1
... A33: Min_Chaos_Rodada_6_Imagem 31 | B33: 1 | C33: 0 | D33: 4 | E33: 1 | F33: 0 | G33: 4 | H33: 0 | I33: 0 | J33: 1 | K33: 1 | L33: 0 | M33: 1 | N33: 1 | O33: 0 | P33: 0 | Q33: 0 | R33: 0 | S33: 1
A34: Total: | B34: =SUM(B3:B33) -> 11 | C34: =SUM(C3:C33) -> 0 | D34: =SUM(D3:D33) -> 19 | E34: =SUM(E3:E33) -> 23 | F34: =SUM(F3:F33) -> 0 | G34: =SUM(G3:G33) -> 57 | H34: =SUM(H3:H33) -> 9 | I34: =SUM(I3:I33) -> 0 | ... S34: =SUM(S3:S33) -> 29
A35: Precisão: | B35: =B34 / (B34 + C34) -> 1 | E35: =E34 / (E34 + F34) -> 1 | H35: =H34 / (H34 + I34) -> 1 | K35: =K34 / (K34 + L34) -> 1 | N35: =N34 / (N34 + O34) -> 1 | Q35: =Q34 / (Q34 + R34) -> 0.083333333
A36: Acurácia | B36: =B34 / (B34 + D34) -> 0.36666667 | E36: =E34 / (E34 + G34) -> 0.2875 | H36: =H34 / (H34 + J34) -> 0.40909091 | K36: =K34 / (K34 + M34) -> 0.52 | N36: =N34 / (N34 + P34) -> 1 | Q36: =Q34 / (Q34 + S34) -> 0.033333333

Sheet rodada 7
B1: Parafusos | E1: Arruelas | H1: Alfinete | K1: Porta Agulhas | N1: Allis | Q1: Anatomica
A2: filename | B2: VP | C2: FP | D2: FN | E2: VP | F2: FP | G2: FN | H2: VP | I2: FP | J2: FN | K2: VP | L2: FP | M2: FN | N2: VP | O2: FP | P2: FN | Q2: VP | R2: FP | S2: FN
A3: Min_Chaos_Rodada_7_Imagem 01 | B3: 1 | C3: 0 | D3: 4 | E3: 1 | F3: 0 | G3: 4 | H3: 0 | I3: 0 | J3: 1 | K3: 1 | L3: 0 | M3: 1 | N3: 1 | O3: 0 | P3: 0 | Q3: 0 | R3: 0 | S3: 1
A4: Min_Chaos_Rodada_7_Imagem 02 | B4: 0 | C4: 0 | D4: 4 | E4: 0 | F4: 0 | G4: 5 | H4: 0 | I4: 0 | J4: 1 | K4: 1 | L4: 0 | M4: 1 | N4: 1 | O4: 0 | P4: 0 | Q4: 0 | R4: 0 | S4: 1
A5: Min_Chaos_Rodada_7_Imagem 03 | B5: 2 | C5: 0 | D5: 1 | E5: 1 | F5: 0 | G5: 4 | H5: 1 | I5: 0 | J5: 0 | K5: 1 | L5: 0 | M5: 1 | N5: 1 | O5: 0 | P5: 0 | Q5: 0 | R5: 0 | S5: 1
A6: Min_Chaos_Rodada_7_Imagem 04 | B6: 0 | C6: 0 | D6: 2 | E6: 0 | F6: 0 | G6: 5 | H6: 1 | I6: 0 | J6: 0 | K6: 1 | L6: 0 | M6: 1 | N6: 1 | O6: 0 | P6: 0 | Q6: 0 | R6: 0 | S6: 1
A7: Min_Chaos_Rodada_7_Imagem 05 | B7: 1 | C7: 0 | D7: 0 | E7: 1 | F7: 0 | G7: 4 | H7: 1 | I7: 0 | J7: 0 | K7: 1 | L7: 0 | M7: 1 | N7: 1 | O7: 0 | P7: 0 | Q7: 0 | R7: 0 | S7: 1
A8: Min_Chaos_Rodada_7_Imagem 06 | B8: 0 | C8: 0 | D8: 0 | E8: 1 | F8: 0 | G8: 4 | H8: 1 | I8: 0 | J8: 0 | K8: 1 | L8: 0 | M8: 1 | N8: 1 | O8: 0 | P8: 0 | Q8: 0 | R8: 0 | S8: 1
A9: Min_Chaos_Rodada_7_Imagem 07 | B9: 0 | C9: 0 | D9: 0 | E9: 1 | F9: 0 | G9: 3 | H9: 1 | I9: 0 | J9: 0 | K9: 1 | L9: 0 | M9: 1 | N9: 1 | O9: 0 | P9: 0 | Q9: 0 | R9: 0 | S9: 1
A10: Min_Chaos_Rodada_7_Imagem 08 | B10: 0 | C10: 0 | D10: 0 | E10: 0 | F10: 0 | G10: 3 | H10: 1 | I10: 0 | J10: 0 | K10: 1 | L10: 0 | M10: 1 | N10: 1 | O10: 0 | P10: 0 | Q10: 0 | R10: 0 | S10: 1
A11: Min_Chaos_Rodada_7_Imagem 09 | B11: 0 | C11: 0 | D11: 0 | E11: 0 | F11: 0 | G11: 2 | H11: 1 | I11: 0 | J11: 0 | K11: 1 | L11: 0 | M11: 1 | N11: 1 | O11: 0 | P11: 0 | Q11: 0 | R11: 0 | S11: 1
A12: Min_Chaos_Rodada_7_Imagem 10 | B12: 0 | C12: 0 | D12: 0 | E12: 1 | F12: 0 | G12: 0 | H12: 1 | I12: 0 | J12: 0 | K12: 1 | L12: 0 | M12: 1 | N12: 1 | O12: 0 | P12: 0 | Q12: 0 | R12: 0 | S12: 1
A13: Min_Chaos_Rodada_7_Imagem 11 | B13: 0 | C13: 0 | D13: 0 | E13: 0 | F13: 0 | G13: 0 | H13: 1 | I13: 0 | J13: 0 | K13: 1 | L13: 0 | M13: 1 | N13: 1 | O13: 0 | P13: 0 | Q13: 0 | R13: 0 | S13: 1
A14: Min_Chaos_Rodada_7_Imagem 12 | B14: 0 | C14: 0 | D14: 0 | E14: 0 | F14: 0 | G14: 0 | H14: 0 | I14: 0 | J14: 0 | K14: 1 | L14: 0 | M14: 1 | N14: 1 | O14: 0 | P14: 0 | Q14: 0 | R14: 0 | S14: 1
... A33: Min_Chaos_Rodada_7_Imagem 31 | B33: 1 | C33: 0 | D33: 4 | E33: 0 | F33: 0 | G33: 5 | H33: 0 | I33: 0 | J33: 1 | K33: 2 | L33: 0 | M33: 0 | N33: 1 | O33: 0 | P33: 0 | Q33: 0 | R33: 0 | S33: 1
A34: Total: | B34: =SUM(B3:B33) -> 7 | C34: =SUM(C3:C33) -> 0 | D34: =SUM(D3:D33) -> 23 | E34: =SUM(E3:E33) -> 8 | F34: =SUM(F3:F33) -> 0 | G34: =SUM(G3:G33) -> 72 | H34: =SUM(H3:H33) -> 10 | I34: =SUM(I3:I33) -> 0 | ... S34: =SUM(S3:S33) -> 30
A35: Precisão: | B35: =B34 / (B34 + C34) -> 1 | E35: =E34 / (E34 + F34) -> 1 | H35: =H34 / (H34 + I34) -> 1 | K35: =K34 / (K34 + L34) -> 1 | N35: =N34 / (N34 + O34) -> 1 | Q35: =Q34 / (Q34 + R34) -> #DIV/0!
A36: Acurácia | B36: =B34 / (B34 + D34) -> 0.23333333 | E36: =E34 / (E34 + G34) -> 0.1 | H36: =H34 / (H34 + J34) -> 0.45454545 | K36: =K34 / (K34 + M34) -> 0.76 | N36: =N34 / (N34 + P34) -> 1 | Q36: =Q34 / (Q34 + S34) -> 0

Sheet rodada 8
B1: Parafusos | E1: Arruelas | H1: Alfinete | K1: Porta Agulhas | N1: Allis | Q1: Anatomica
A2: filename | B2: VP | C2: FP | D2: FN | E2: VP | F2: FP | G2: FN | H2: VP | I2: FP | J2: FN | K2: VP | L2: FP | M2: FN | N2: VP | O2: FP | P2: FN | Q2: VP | R2: FP | S2: FN
A3: Min_Chaos_Rodada_8_Imagem 01 | B3: 2 | C3: 0 | D3: 3 | E3: 0 | F3: 0 | G3: 5 | H3: 0 | I3: 0 | J3: 1 | K3: 1 | L3: 1 | M3: 1 | N3: 1 | O3: 0 | P3: 0 | Q3: 0 | R3: 0 | S3: 1
A4: Min_Chaos_Rodada_8_Imagem 02 | B4: 1 | C4: 0 | D4: 3 | E4: 0 | F4: 0 | G4: 5 | H4: 0 | I4: 0 | J4: 1 | K4: 1 | L4: 1 | M4: 1 | N4: 1 | O4: 0 | P4: 0 | Q4: 0 | R4: 0 | S4: 1
A5: Min_Chaos_Rodada_8_Imagem 03 | B5: 1 | C5: 0 | D5: 2 | E5: 0 | F5: 0 | G5: 5 | H5: 0 | I5: 0 | J5: 1 | K5: 1 | L5: 1 | M5: 1 | N5: 1 | O5: 0 | P5: 0 | Q5: 0 | R5: 0 | S5: 1
A6: Min_Chaos_Rodada_8_Imagem 04 | B6: 2 | C6: 0 | D6: 0 | E6: 0 | F6: 0 | G6: 5 | H6: 0 | I6: 0 | J6: 1 | K6: 1 | L6: 1 | M6: 1 | N6: 1 | O6: 0 | P6: 0 | Q6: 0 | R6: 0 | S6: 1
A7: Min_Chaos_Rodada_8_Imagem 05 | B7: 1 | C7: 0 | D7: 0 | E7: 0 | F7: 0 | G7: 5 | H7: 0 | I7: 0 | J7: 1 | K7: 1 | L7: 1 | M7: 1 | N7: 1 | O7: 0 | P7: 0 | Q7: 0 | R7: 0 | S7: 1
A8: Min_Chaos_Rodada_8_Imagem 06 | B8: 0 | C8: 0 | D8: 0 | E8: 0 | F8: 0 | G8: 5 | H8: 0 | I8: 0 | J8: 1 | K8: 2 | L8: 0 | M8: 0 | N8: 1 | O8: 0 | P8: 0 | Q8: 0 | R8: 0 | S8: 1
A9: Min_Chaos_Rodada_8_Imagem 07 | B9: 0 | C9: 0 | D9: 0 | E9: 1 | F9: 0 | G9: 3 | H9: 0 | I9: 0 | J9: 1 | K9: 2 | L9: 0 | M9: 0 | N9: 1 | O9: 0 | P9: 0 | Q9: 0 | R9: 0 | S9: 1
A10: Min_Chaos_Rodada_8_Imagem 08 | B10: 0 | C10: 0 | D10: 0 | E10: 0 | F10: 0 | G10: 3 | H10: 0 | I10: 0 | J10: 1 | K10: 2 | L10: 0 | M10: 0 | N10: 1 | O10: 0 | P10: 0 | Q10: 0 | R10: 0 | S10: 1
A11: Min_Chaos_Rodada_8_Imagem 09 | B11: 0 | C11: 0 | D11: 0 | E11: 0 | F11: 0 | G11: 2 | H11: 1 | I11: 0 | J11: 0 | K11: 2 | L11: 0 | M11: 0 | N11: 1 | O11: 0 | P11: 0 | Q11: 0 | R11: 0 | S11: 1
A12: Min_Chaos_Rodada_8_Imagem 10 | B12: 0 | C12: 0 | D12: 0 | E12: 0 | F12: 0 | G12: 1 | H12: 0 | I12: 0 | J12: 1 | K12: 2 | L12: 0 | M12: 0 | N12: 1 | O12: 0 | P12: 0 | Q12: 0 | R12: 0 | S12: 1
A13: Min_Chaos_Rodada_8_Imagem 11 | B13: 0 | C13: 0 | D13: 0 | E13: 0 | F13: 0 | G13: 0 | H13: 0 | I13: 0 | J13: 1 | K13: 2 | L13: 0 | M13: 0 | N13: 1 | O13: 0 | P13: 0 | Q13: 0 | R13: 0 | S13: 1
A14: Min_Chaos_Rodada_8_Imagem 12 | B14: 0 | C14: 0 | D14: 0 | E14: 0 | F14: 0 | G14: 0 | H14: 0 | I14: 0 | J14: 0 | K14: 2 | L14: 0 | M14: 0 | N14: 1 | O14: 0 | P14: 0 | Q14: 0 | R14: 0 | S14: 1
... A33: Min_Chaos_Rodada_8_Imagem 31 | B33: 1 | C33: 0 | D33: 4 | E33: 0 | F33: 0 | G33: 5 | H33: 0 | I33: 0 | J33: 1 | K33: 2 | L33: 0 | M33: 0 | N33: 0 | O33: 0 | P33: 1 | Q33: 0 | R33: 0 | S33: 1
A34: Total: | B34: =SUM(B3:B33) -> 9 | C34: =SUM(C3:C33) -> 0 | D34: =SUM(D3:D33) -> 21 | E34: =SUM(E3:E33) -> 7 | F34: =SUM(F3:F33) -> 0 | G34: =SUM(G3:G33) -> 73 | H34: =SUM(H3:H33) -> 2 | I34: =SUM(I3:I33) -> 0 | ... S34: =SUM(S3:S33) -> 30
A35: Precisão: | B35: =B34 / (B34 + C34) -> 1 | E35: =E34 / (E34 + F34) -> 1 | H35: =H34 / (H34 + I34) -> 1 | K35: =K34 / (K34 + L34) -> 0.80392157 | N35: =N34 / (N34 + O34) -> 1 | Q35: =Q34 / (Q34 + R34) -> 0
A36: Acurácia | B36: =B34 / (B34 + D34) -> 0.3 | E36: =E34 / (E34 + G34) -> 0.0875 | H36: =H34 / (H34 + J34) -> 0.090909091 | K36: =K34 / (K34 + M34) -> 0.82 | N36: =N34 / (N34 + P34) -> 0.57142857 | Q36: =Q34 / (Q34 + S34) -> 0

Sheet rodada 9
B1: Parafusos | E1: Arruelas | H1: Alfinete | K1: Porta Agulhas | N1: Allis | Q1: Anatomica
A2: filename | B2: VP | C2: FP | D2: FN | E2: VP | F2: FP | G2: FN | H2: VP | I2: FP | J2: FN | K2: VP | L2: FP | M2: FN | N2: VP | O2: FP | P2: FN | Q2: VP | R2: FP | S2: FN
A3: Min_Chaos_Rodada_9_Imagem 01 | B3: 0 | C3: 0 | D3: 5 | E3: 1 | F3: 0 | G3: 4 | H3: 0 | I3: 0 | J3: 1 | K3: 1 | L3: 0 | M3: 1 | N3: 1 | O3: 0 | P3: 0 | Q3: 0 | R3: 0 | S3: 1
A4: Min_Chaos_Rodada_9_Imagem 02 | B4: 0 | C4: 0 | D4: 4 | E4: 0 | F4: 0 | G4: 5 | H4: 0 | I4: 0 | J4: 1 | K4: 1 | L4: 0 | M4: 1 | N4: 1 | O4: 0 | P4: 0 | Q4: 0 | R4: 0 | S4: 1
A5: Min_Chaos_Rodada_9_Imagem 03 | B5: 1 | C5: 0 | D5: 2 | E5: 1 | F5: 0 | G5: 4 | H5: 0 | I5: 0 | J5: 1 | K5: 1 | L5: 0 | M5: 1 | N5: 1 | O5: 0 | P5: 0 | Q5: 0 | R5: 0 | S5: 1
A6: Min_Chaos_Rodada_9_Imagem 04 | B6: 1 | C6: 0 | D6: 1 | E6: 1 | F6: 0 | G6: 4 | H6: 0 | I6: 0 | J6: 1 | K6: 1 | L6: 0 | M6: 1 | N6: 1 | O6: 0 | P6: 0 | Q6: 0 | R6: 0 | S6: 1
A7: Min_Chaos_Rodada_9_Imagem 05 | B7: 0 | C7: 0 | D7: 1 | E7: 1 | F7: 0 | G7: 4 | H7: 0 | I7: 0 | J7: 1 | K7: 1 | L7: 0 | M7: 1 | N7: 1 | O7: 0 | P7: 0 | Q7: 0 | R7: 0 | S7: 1
A8: Min_Chaos_Rodada_9_Imagem 06 | B8: 0 | C8: 0 | D8: 0 | E8: 1 | F8: 0 | G8: 4 | H8: 0 | I8: 0 | J8: 1 | K8: 1 | L8: 0 | M8: 1 | N8: 1 | O8: 0 | P8: 0 | Q8: 0 | R8: 0 | S8: 1
A9: Min_Chaos_Rodada_9_Imagem 07 | B9: 0 | C9: 0 | D9: 0 | E9: 2 | F9: 0 | G9: 2 | H9: 0 | I9: 0 | J9: 1 | K9: 1 | L9: 0 | M9: 1 | N9: 1 | O9: 0 | P9: 0 | Q9: 0 | R9: 0 | S9: 1
A10: Min_Chaos_Rodada_9_Imagem 08 | B10: 0 | C10: 0 | D10: 0 | E10: 1 | F10: 0 | G10: 2 | H10: 0 | I10: 0 | J10: 1 | K10: 1 | L10: 0 | M10: 1 | N10: 1 | O10: 0 | P10: 0 | Q10: 0 | R10: 0 | S10: 1
A11: Min_Chaos_Rodada_9_Imagem 09 | B11: 0 | C11: 0 | D11: 0 | E11: 0 | F11: 0 | G11: 2 | H11: 0 | I11: 0 | J11: 1 | K11: 1 | L11: 0 | M11: 1 | N11: 1 | O11: 0 | P11: 0 | Q11: 0 | R11: 0 | S11: 1
A12: Min_Chaos_Rodada_9_Imagem 10 | B12: 0 | C12: 0 | D12: 0 | E12: 1 | F12: 0 | G12: 0 | H12: 0 | I12: 0 | J12: 1 | K12: 1 | L12: 0 | M12: 1 | N12: 1 | O12: 0 | P12: 0 | Q12: 0 | R12: 0 | S12: 1
A13: Min_Chaos_Rodada_9_Imagem 11 | B13: 0 | C13: 0 | D13: 0 | E13: 0 | F13: 0 | G13: 0 | H13: 0 | I13: 0 | J13: 1 | K13: 1 | L13: 0 | M13: 1 | N13: 1 | O13: 0 | P13: 0 | Q13: 0 | R13: 0 | S13: 1
A14: Min_Chaos_Rodada_9_Imagem 12 | B14: 0 | C14: 0 | D14: 0 | E14: 0 | F14: 0 | G14: 0 | H14: 0 | I14: 0 | J14: 0 | K14: 2 | L14: 0 | M14: 0 | N14: 1 | O14: 0 | P14: 0 | Q14: 0 | R14: 0 | S14: 1
... A33: Min_Chaos_Rodada_9_Imagem 31 | B33: 0 | C33: 0 | D33: 5 | E33: 3 | F33: 0 | G33: 2 | H33: 0 | I33: 0 | J33: 1 | K33: 1 | L33: 0 | M33: 1 | N33: 1 | O33: 0 | P33: 0 | Q33: 0 | R33: 0 | S33: 1
A34: Total: | B34: =SUM(B3:B33) -> 3 | C34: =SUM(C3:C33) -> 0 | D34: =SUM(D3:D33) -> 27 | E34: =SUM(E3:E33) -> 34 | F34: =SUM(F3:F33) -> 5 | G34: =SUM(G3:G33) -> 46 | H34: =SUM(H3:H33) -> 8 | I34: =SUM(I3:I33) -> 0 | ... S34: =SUM(S3:S33) -> 30
A35: Precisão: | B35: =B34 / (B34 + C34) -> 1 | E35: =E34 / (E34 + F34) -> 0.87179487 | H35: =H34 / (H34 + I34) -> 1 | K35: =K34 / (K34 + L34) -> 0.96551724 | N35: =N34 / (N34 + O34) -> 1 | Q35: =Q34 / (Q34 + R34) -> #DIV/0!
A36: Acurácia | B36: =B34 / (B34 + D34) -> 0.1 | E36: =E34 / (E34 + G34) -> 0.425 | H36: =H34 / (H34 + J34) -> 0.36363636 | K36: =K34 / (K34 + M34) -> 0.56 | N36: =N34 / (N34 + P34) -> 0.96428571 | Q36: =Q34 / (Q34 + S34) -> 0

Sheet rodada 10
B1: Parafusos | E1: Arruelas | H1: Alfinete | K1: Porta Agulhas | N1: Allis | Q1: Anatomica
A2: filename | B2: VP | C2: FP | D2: FN | E2: VP | F2: FP | G2: FN | H2: VP | I2: FP | J2: FN | K2: VP | L2: FP | M2: FN | N2: VP | O2: FP | P2: FN | Q2: VP | R2: FP | S2: FN
A3: Min_Chaos_Rodada_10_Imagem 01 | B3: 0 | C3: 0 | D3: 5 | E3: 3 | F3: 0 | G3: 2 | H3: 1 | I3: 0 | J3: 0 | K3: 2 | L3: 0 | M3: 0 | N3: 1 | O3: 0 | P3: 0 | Q3: 0 | R3: 0 | S3: 1
A4: Min_Chaos_Rodada_10_Imagem 02 | B4: 0 | C4: 0 | D4: 4 | E4: 2 | F4: 0 | G4: 3 | H4: 1 | I4: 0 | J4: 0 | K4: 2 | L4: 0 | M4: 0 | N4: 1 | O4: 0 | P4: 0 | Q4: 0 | R4: 0 | S4: 1
A5: Min_Chaos_Rodada_10_Imagem 03 | B5: 1 | C5: 0 | D5: 2 | E5: 2 | F5: 0 | G5: 3 | H5: 1 | I5: 0 | J5: 0 | K5: 2 | L5: 0 | M5: 0 | N5: 1 | O5: 0 | P5: 0 | Q5: 0 | R5: 0 | S5: 1
A6: Min_Chaos_Rodada_10_Imagem 04 | B6: 1 | C6: 0 | D6: 1 | E6: 3 | F6: 0 | G6: 2 | H6: 1 | I6: 0 | J6: 0 | K6: 2 | L6: 0 | M6: 0 | N6: 1 | O6: 0 | P6: 0 | Q6: 0 | R6: 0 | S6: 1
A7: Min_Chaos_Rodada_10_Imagem 05 | B7: 0 | C7: 0 | D7: 1 | E7: 3 | F7: 0 | G7: 2 | H7: 1 | I7: 0 | J7: 0 | K7: 2 | L7: 0 | M7: 0 | N7: 1 | O7: 0 | P7: 0 | Q7: 0 | R7: 0 | S7: 1
A8: Min_Chaos_Rodada_10_Imagem 06 | B8: 0 | C8: 0 | D8: 0 | E8: 3 | F8: 0 | G8: 2 | H8: 1 | I8: 0 | J8: 0 | K8: 2 | L8: 0 | M8: 0 | N8: 1 | O8: 0 | P8: 0 | Q8: 0 | R8: 0 | S8: 1
A9: Min_Chaos_Rodada_10_Imagem 07 | B9: 0 | C9: 0 | D9: 0 | E9: 3 | F9: 0 | G9: 1 | H9: 1 | I9: 0 | J9: 0 | K9: 2 | L9: 0 | M9: 0 | N9: 1 | O9: 0 | P9: 0 | Q9: 0 | R9: 0 | S9: 1
A10: Min_Chaos_Rodada_10_Imagem 08 | B10: 0 | C10: 0 | D10: 0 | E10: 2 | F10: 0 | G10: 1 | H10: 1 | I10: 0 | J10: 0 | K10: 2 | L10: 0 | M10: 0 | N10: 1 | O10: 0 | P10: 0 | Q10: 0 | R10: 0 | S10: 1
A11: Min_Chaos_Rodada_10_Imagem 09 | B11: 0 | C11: 0 | D11: 0 | E11: 2 | F11: 0 | G11: 0 | H11: 1 | I11: 0 | J11: 0 | K11: 2 | L11: 0 | M11: 0 | N11: 1 | O11: 0 | P11: 0 | Q11: 0 | R11: 0 | S11: 1
A12: Min_Chaos_Rodada_10_Imagem 10 | B12: 0 | C12: 0 | D12: 0 | E12: 1 | F12: 0 | G12: 0 | H12: 1 | I12: 0 | J12: 0 | K12: 2 | L12: 0 | M12: 0 | N12: 1 | O12: 0 | P12: 0 | Q12: 0 | R12: 0 | S12: 1
A13: Min_Chaos_Rodada_10_Imagem 11 | B13: 0 | C13: 0 | D13: 0 | E13: 0 | F13: 0 | G13: 0 | H13: 1 | I13: 0 | J13: 0 | K13: 2 | L13: 0 | M13: 0 | N13: 1 | O13: 0 | P13: 0 | Q13: 0 | R13: 0 | S13: 1
A14: Min_Chaos_Rodada_10_Imagem 12 | B14: 0 | C14: 0 | D14: 0 | E14: 0 | F14: 0 | G14: 0 | H14: 0 | I14: 0 | J14: 0 | K14: 2 | L14: 0 | M14: 0 | N14: 1 | O14: 0 | P14: 0 | Q14: 0 | R14: 0 | S14: 1
... A33: Min_Chaos_Rodada_10_Imagem 31 | B33: 0 | C33: 0 | D33: 5 | E33: 3 | F33: 0 | G33: 2 | H33: 1 | I33: 0 | J33: 0 | K33: 2 | L33: 0 | M33: 0 | N33: 0 | O33: 0 | P33: 1 | Q33: 0 | R33: 0 | S33: 1
A34: Total: | B34: =SUM(B3:B33) -> 3 | C34: =SUM(C3:C33) -> 0 | D34: =SUM(D3:D33) -> 27 | E34: =SUM(E3:E33) -> 48 | F34: =SUM(F3:F33) -> 0 | G34: =SUM(G3:G33) -> 32 | H34: =SUM(H3:H33) -> 22 | I34: =SUM(I3:I33) -> 0 | ... S34: =SUM(S3:S33) -> 30
A35: Precisão: | B35: =B34 / (B34 + C34) -> 1 | E35: =E34 / (E34 + F34) -> 1 | H35: =H34 / (H34 + I34) -> 1 | K35: =K34 / (K34 + L34) -> 1 | N35: =N34 / (N34 + O34) -> 1 | Q35: =Q34 / (Q34 + R34) -> #DIV/0!
A36: Acurácia | B36: =B34 / (B34 + D34) -> 0.1 | E36: =E34 / (E34 + G34) -> 0.6 | H36: =H34 / (H34 + J34) -> 1 | K36: =K34 / (K34 + M34) -> 1 | N36: =N34 / (N34 + P34) -> 0.53571429 | Q36: =Q34 / (Q34 + S34) -> 0

Sheet rodada 11
B1: Parafusos | E1: Arruelas | H1: Alfinete | K1: Porta Agulhas | N1: Allis | Q1: Anatomica
A2: filename | B2: VP | C2: FP | D2: FN | E2: VP | F2: FP | G2: FN | H2: VP | I2: FP | J2: FN | K2: VP | L2: FP | M2: FN | N2: VP | O2: FP | P2: FN | Q2: VP | R2: FP | S2: FN
A3: Min_Chaos_Rodada_11_Imagem 01 | B3: 1 | C3: 0 | D3: 4 | E3: 1 | F3: 0 | G3: 4 | H3: 1 | I3: 0 | J3: 0 | K3: 2 | L3: 0 | M3: 0 | N3: 0 | O3: 0 | P3: 1 | Q3: 0 | R3: 0 | S3: 1
A4: Min_Chaos_Rodada_11_Imagem 02 | B4: 1 | C4: 0 | D4: 3 | E4: 1 | F4: 0 | G4: 4 | H4: 0 | I4: 0 | J4: 1 | K4: 1 | L4: 0 | M4: 1 | N4: 0 | O4: 0 | P4: 1 | Q4: 0 | R4: 0 | S4: 1
A5: Min_Chaos_Rodada_11_Imagem 03 | B5: 2 | C5: 0 | D5: 1 | E5: 1 | F5: 0 | G5: 4 | H5: 1 | I5: 0 | J5: 0 | K5: 1 | L5: 0 | M5: 1 | N5: 0 | O5: 0 | P5: 1 | Q5: 0 | R5: 0 | S5: 1
A6: Min_Chaos_Rodada_11_Imagem 04 | B6: 1 | C6: 0 | D6: 1 | E6: 1 | F6: 0 | G6: 4 | H6: 1 | I6: 0 | J6: 0 | K6: 2 | L6: 0 | M6: 0 | N6: 0 | O6: 0 | P6: 1 | Q6: 0 | R6: 0 | S6: 1
A7: Min_Chaos_Rodada_11_Imagem 05 | B7: 1 | C7: 0 | D7: 0 | E7: 1 | F7: 0 | G7: 4 | H7: 1 | I7: 0 | J7: 0 | K7: 1 | L7: 0 | M7: 1 | N7: 0 | O7: 0 | P7: 1 | Q7: 0 | R7: 0 | S7: 1
A8: Min_Chaos_Rodada_11_Imagem 06 | B8: 0 | C8: 0 | D8: 0 | E8: 1 | F8: 0 | G8: 4 | H8: 1 | I8: 0 | J8: 0 | K8: 1 | L8: 0 | M8: 1 | N8: 0 | O8: 0 | P8: 1 | Q8: 0 | R8: 0 | S8: 1
A9: Min_Chaos_Rodada_11_Imagem 07 | B9: 0 | C9: 0 | D9: 0 | E9: 1 | F9: 0 | G9: 3 | H9: 1 | I9: 0 | J9: 0 | K9: 1 | L9: 0 | M9: 1 | N9: 0 | O9: 0 | P9: 1 | Q9: 0 | R9: 0 | S9: 1
A10: Min_Chaos_Rodada_11_Imagem 08 | B10: 0 | C10: 0 | D10: 0 | E10: 2 | F10: 0 | G10: 1 | H10: 1 | I10: 0 | J10: 0 | K10: 1 | L10: 0 | M10: 1 | N10: 0 | O10: 0 | P10: 1 | Q10: 0 | R10: 0 | S10: 1
A11: Min_Chaos_Rodada_11_Imagem 09 | B11: 0 | C11: 0 | D11: 0 | E11: 2 | F11: 0 | G11: 0 | H11: 1 | I11: 0 | J11: 0 | K11: 2 | L11: 0 | M11: 0 | N11: 0 | O11: 0 | P11: 1 | Q11: 0 | R11: 0 | S11: 1
A12: Min_Chaos_Rodada_11_Imagem 10 | B12: 0 | C12: 0 | D12: 0 | E12: 1 | F12: 0 | G12: 0 | H12: 1 | I12: 0 | J12: 0 | K12: 2 | L12: 0 | M12: 0 | N12: 0 | O12: 0 | P12: 1 | Q12: 0 | R12: 0 | S12: 1
A13: Min_Chaos_Rodada_11_Imagem 11 | B13: 0 | C13: 0 | D13: 0 | E13: 0 | F13: 0 | G13: 0 | H13: 1 | I13: 0 | J13: 0 | K13: 2 | L13: 0 | M13: 0 | N13: 0 | O13: 0 | P13: 1 | Q13: 0 | R13: 0 | S13: 1
A14: Min_Chaos_Rodada_11_Imagem 12 | B14: 0 | C14: 0 | D14: 0 | E14: 0 | F14: 0 | G14: 0 | H14: 0 | I14: 0 | J14: 0 | K14: 1 | L14: 0 | M14: 1 | N14: 0 | O14: 0 | P14: 1 | Q14: 0 | R14: 0 | S14: 1
... A33: Min_Chaos_Rodada_11_Imagem 31 | B33: 0 | C33: 0 | D33: 5 | E33: 0 | F33: 0 | G33: 5 | H33: 1 | I33: 0 | J33: 0 | K33: 1 | L33: 0 | M33: 1 | N33: 0 | O33: 0 | P33: 1 | Q33: 0 | R33: 1 | S33: 1
A34: Total: | B34: =SUM(B3:B33) -> 6 | C34: =SUM(C3:C33) -> 0 | D34: =SUM(D3:D33) -> 24 | E34: =SUM(E3:E33) -> 14 | F34: =SUM(F3:F33) -> 0 | G34: =SUM(G3:G33) -> 66 | H34: =SUM(H3:H33) -> 21 | I34: =SUM(I3:I33) -> 0 | ... S34: =SUM(S3:S33) -> 30
A35: Precisão: | B35: =B34 / (B34 + C34) -> 1 | E35: =E34 / (E34 + F34) -> 1 | H35: =H34 / (H34 + I34) -> 1 | K35: =K34 / (K34 + L34) -> 0.96875 | N35: =N34 / (N34 + O34) -> 1 | Q35: =Q34 / (Q34 + R34) -> 0
A36: Acurácia | B36: =B34 / (B34 + D34) -> 0.2 | E36: =E34 / (E34 + G34) -> 0.175 | H36: =H34 / (H34 + J34) -> 0.95454545 | K36: =K34 / (K34 + M34) -> 0.62 | N36: =N34 / (N34 + P34) -> 0.35714286 | Q36: =Q34 / (Q34 + S34) -> 0

Sheet rodada 12
B1: Parafusos | E1: Arruelas | H1: Alfinete | K1: Porta Agulhas | N1: Allis | Q1: Anatomica
A2: filename | B2: VP | C2: FP | D2: FN | E2: VP | F2: FP | G2: FN | H2: VP | I2: FP | J2: FN | K2: VP | L2: FP | M2: FN | N2: VP | O2: FP | P2: FN | Q2: VP | R2: FP | S2: FN
A3: Min_Chaos_Rodada_12_Imagem 01 | B3: 0 | C3: 0 | D3: 5 | E3: 1 | F3: 0 | G3: 4 | H3: 1 | I3: 0 | J3: 0 | K3: 1 | L3: 1 | M3: 1 | N3: 0 | O3: 0 | P3: 1 | Q3: 0 | R3: 1 | S3: 1
A4: Min_Chaos_Rodada_12_Imagem 02 | B4: 0 | C4: 0 | D4: 4 | E4: 1 | F4: 0 | G4: 4 | H4: 1 | I4: 0 | J4: 0 | K4: 1 | L4: 1 | M4: 1 | N4: 0 | O4: 0 | P4: 1 | Q4: 0 | R4: 1 | S4: 1
A5: Min_Chaos_Rodada_12_Imagem 03 | B5: 0 | C5: 0 | D5: 3 | E5: 1 | F5: 0 | G5: 4 | H5: 1 | I5: 0 | J5: 0 | K5: 1 | L5: 1 | M5: 1 | N5: 0 | O5: 0 | P5: 1 | Q5: 0 | R5: 1 | S5: 1
A6: Min_Chaos_Rodada_12_Imagem 04 | B6: 1 | C6: 0 | D6: 1 | E6: 1 | F6: 0 | G6: 4 | H6: 1 | I6: 0 | J6: 0 | K6: 1 | L6: 1 | M6: 1 | N6: 0 | O6: 0 | P6: 1 | Q6: 0 | R6: 1 | S6: 1
A7: Min_Chaos_Rodada_12_Imagem 05 | B7: 1 | C7: 0 | D7: 0 | E7: 1 | F7: 0 | G7: 4 | H7: 1 | I7: 0 | J7: 0 | K7: 2 | L7: 0 | M7: 0 | N7: 0 | O7: 0 | P7: 1 | Q7: 0 | R7: 1 | S7: 1
A8: Min_Chaos_Rodada_12_Imagem 06 | B8: 0 | C8: 0 | D8: 0 | E8: 0 | F8: 0 | G8: 5 | H8: 1 | I8: 0 | J8: 0 | K8: 1 | L8: 1 | M8: 1 | N8: 0 | O8: 0 | P8: 1 | Q8: 0 | R8: 1 | S8: 1
A9: Min_Chaos_Rodada_12_Imagem 07 | B9: 0 | C9: 0 | D9: 0 | E9: 0 | F9: 0 | G9: 4 | H9: 1 | I9: 0 | J9: 0 | K9: 1 | L9: 1 | M9: 1 | N9: 0 | O9: 0 | P9: 1 | Q9: 0 | R9: 1 | S9: 1
A10: Min_Chaos_Rodada_12_Imagem 08 | B10: 0 | C10: 0 | D10: 0 | E10: 1 | F10: 0 | G10: 2 | H10: 1 | I10: 0 | J10: 0 | K10: 1 | L10: 1 | M10: 1 | N10: 0 | O10: 0 | P10: 1 | Q10: 0 | R10: 1 | S10: 1
A11: Min_Chaos_Rodada_12_Imagem 09 | B11: 0 | C11: 0 | D11: 0 | E11: 1 | F11: 0 | G11: 1 | H11: 1 | I11: 0 | J11: 0 | K11: 1 | L11: 1 | M11: 1 | N11: 0 | O11: 0 | P11: 1 | Q11: 0 | R11: 1 | S11: 1
A12: Min_Chaos_Rodada_12_Imagem 10 | B12: 0 | C12: 0 | D12: 0 | E12: 0 | F12: 0 | G12: 1 | H12: 1 | I12: 0 | J12: 0 | K12: 1 | L12: 1 | M12: 1 | N12: 0 | O12: 0 | P12: 1 | Q12: 0 | R12: 1 | S12: 1
A13: Min_Chaos_Rodada_12_Imagem 11 | B13: 0 | C13: 0 | D13: 0 | E13: 0 | F13: 0 | G13: 0 | H13: 1 | I13: 0 | J13: 0 | K13: 2 | L13: 0 | M13: 0 | N13: 0 | O13: 0 | P13: 1 | Q13: 0 | R13: 1 | S13: 1
A14: Min_Chaos_Rodada_12_Imagem 12 | B14: 0 | C14: 0 | D14: 0 | E14: 0 | F14: 0 | G14: 0 | H14: 0 | I14: 0 | J14: 0 | K14: 2 | L14: 0 | M14: 0 | N14: 0 | O14: 0 | P14: 1 | Q14: 0 | R14: 1 | S14: 1
... A33: Min_Chaos_Rodada_12_Imagem 31 | B33: 1 | C33: 0 | D33: 4 | E33: 0 | F33: 0 | G33: 5 | H33: 0 | I33: 0 | J33: 1 | K33: 1 | L33: 0 | M33: 1 | N33: 0 | O33: 0 | P33: 1 | Q33: 0 | R33: 1 | S33: 1
A34: Total: | B34: =SUM(B3:B33) -> 6 | C34: =SUM(C3:C33) -> 0 | D34: =SUM(D3:D33) -> 24 | E34: =SUM(E3:E33) -> 11 | F34: =SUM(F3:F33) -> 0 | G34: =SUM(G3:G33) -> 69 | H34: =SUM(H3:H33) -> 19 | I34: =SUM(I3:I33) -> 0 | ... S34: =SUM(S3:S33) -> 30
A35: Precisão: | B35: =B34 / (B34 + C34) -> 1 | E35: =E34 / (E34 + F34) -> 1 | H35: =H34 / (H34 + I34) -> 1 | K35: =K34 / (K34 + L34) -> 0.65454545 | N35: =N34 / (N34 + O34) -> 1 | Q35: =Q34 / (Q34 + R34) -> 0
A36: Acurácia | B36: =B34 / (B34 + D34) -> 0.2 | E36: =E34 / (E34 + G34) -> 0.1375 | H36: =H34 / (H34 + J34) -> 0.86363636 | K36: =K34 / (K34 + M34) -> 0.72 | N36: =N34 / (N34 + P34) -> 0.071428571 | Q36: =Q34 / (Q34 + S34) -> 0

Sheet rodada 13
B1: Parafusos | E1: Arruelas | H1: Alfinete | K1: Porta Agulhas | N1: Allis | Q1: Anatomica
A2: filename | B2: VP | C2: FP | D2: FN | E2: VP | F2: FP | G2: FN | H2: VP | I2: FP | J2: FN | K2: VP | L2: FP | M2: FN | N2: VP | O2: FP | P2: FN | Q2: VP | R2: FP | S2: FN
A3: Min_Chaos_Rodada_13_Imagem 01 | B3: 0 | C3: 0 | D3: 5 | E3: 0 | F3: 0 | G3: 5 | H3: 0 | I3: 0 | J3: 1 | K3: 2 | L3: 1 | M3: 0 | N3: 0 | O3: 0 | P3: 1 | Q3: 0 | R3: 0 | S3: 1
A4: Min_Chaos_Rodada_13_Imagem 02 | B4: 0 | C4: 0 | D4: 4 | E4: 0 | F4: 0 | G4: 5 | H4: 0 | I4: 0 | J4: 1 | K4: 1 | L4: 1 | M4: 1 | N4: 0 | O4: 0 | P4: 1 | Q4: 0 | R4: 1 | S4: 1
A5: Min_Chaos_Rodada_13_Imagem 03 | B5: 2 | C5: 1 | D5: 1 | E5: 0 | F5: 0 | G5: 5 | H5: 0 | I5: 0 | J5: 1 | K5: 1 | L5: 2 | M5: 1 | N5: 0 | O5: 0 | P5: 1 | Q5: 0 | R5: 0 | S5: 1
A6: Min_Chaos_Rodada_13_Imagem 04 | B6: 1 | C6: 0 | D6: 1 | E6: 0 | F6: 0 | G6: 5 | H6: 0 | I6: 0 | J6: 1 | K6: 0 | L6: 2 | M6: 2 | N6: 0 | O6: 0 | P6: 1 | Q6: 0 | R6: 1 | S6: 1
A7: Min_Chaos_Rodada_13_Imagem 05 | B7: 1 | C7: 0 | D7: 0 | E7: 0 | F7: 0 | G7: 5 | H7: 0 | I7: 0 | J7: 1 | K7: 1 | L7: 2 | M7: 1 | N7: 0 | O7: 0 | P7: 1 | Q7: 0 | R7: 0 | S7: 1
A8: Min_Chaos_Rodada_13_Imagem 06 | B8: 0 | C8: 0 | D8: 0 | E8: 0 | F8: 0 | G8: 5 | H8: 0 | I8: 0 | J8: 1 | K8: 1 | L8: 2 | M8: 1 | N8: 0 | O8: 0 | P8: 1 | Q8: 0 | R8: 0 | S8: 1
A9: Min_Chaos_Rodada_13_Imagem 07 | B9: 0 | C9: 0 | D9: 0 | E9: 0 | F9: 0 | G9: 4 | H9: 0 | I9: 0 | J9: 1 | K9: 1 | L9: 2 | M9: 1 | N9: 0 | O9: 0 | P9: 1 | Q9: 0 | R9: 0 | S9: 1
A10: Min_Chaos_Rodada_13_Imagem 08 | B10: 0 | C10: 0 | D10: 0 | E10: 0 | F10: 0 | G10: 3 | H10: 0 | I10: 0 | J10: 1 | K10: 1 | L10: 2 | M10: 1 | N10: 0 | O10: 0 | P10: 1 | Q10: 0 | R10: 0 | S10: 1
A11: Min_Chaos_Rodada_13_Imagem 09 | B11: 0 | C11: 0 | D11: 0 | E11: 0 | F11: 0 | G11: 2 | H11: 0 | I11: 0 | J11: 1 | K11: 1 | L11: 1 | M11: 1 | N11: 0 | O11: 0 | P11: 1 | Q11: 0 | R11: 0 | S11: 1
A12: Min_Chaos_Rodada_13_Imagem 10 | B12: 0 | C12: 0 | D12: 0 | E12: 0 | F12: 0 | G12: 1 | H12: 0 | I12: 0 | J12: 1 | K12: 1 | L12: 2 | M12: 1 | N12: 0 | O12: 0 | P12: 1 | Q12: 0 | R12: 0 | S12: 1
A13: Min_Chaos_Rodada_13_Imagem 11 | B13: 0 | C13: 0 | D13: 0 | E13: 0 | F13: 0 | G13: 0 | H13: 0 | I13: 0 | J13: 1 | K13: 1 | L13: 2 | M13: 1 | N13: 0 | O13: 0 | P13: 1 | Q13: 0 | R13: 0 | S13: 1
A14: Min_Chaos_Rodada_13_Imagem 12 | B14: 0 | C14: 0 | D14: 0 | E14: 0 | F14: 0 | G14: 0 | H14: 0 | I14: 0 | J14: 0 | K14: 2 | L14: 1 | M14: 0 | N14: 0 | O14: 0 | P14: 1 | Q14: 0 | R14: 0 | S14: 1
... A32: Min_Chaos_Rodada_13_Imagem 30 | B32: 0 | C32: 0 | D32: 5 | E32: 0 | F32: 0 | G32: 5 | H32: 0 | I32: 0 | J32: 1 | K32: 2 | L32: 0 | M32: 0 | N32: 0 | O32: 0 | P32: 1 | Q32: 0 | R32: 0 | S32: 1
A33: Total: | B33: =SUM(B3:B32) -> 6 | C33: =SUM(C3:C32) -> 1 | D33: =SUM(D3:D32) -> 24 | E33: =SUM(E3:E32) -> 2 | F33: =SUM(F3:F32) -> 0 | G33: =SUM(G3:G32) -> 78 | H33: =SUM(H3:H32) -> 8 | I33: =SUM(I3:I32) -> 0 | ... S33: =SUM(S3:S32) -> 26
A34: Precisão: | B34: =B33 / (B33 + C33) -> 0.85714286 | E34: =E33 / (E33 + F33) -> 1 | H34: =H33 / (H33 + I33) -> 1 | K34: =K33 / (K33 + L33) -> 0.61666667 | N34: =N33 / (N33 + O33) -> 1 | Q34: =Q33 / (Q33 + R33) -> 0.6
A35: Acurácia | B35: =B33 / (B33 + D33) -> 0.2 | E35: =E33 / (E33 + G33) -> 0.025 | H35: =H33 / (H33 + J33) -> 0.36363636 | K35: =K33 / (K33 + M33) -> 0.75510204 | N35: =N33 / (N33 + P33) -> 0.22222222 | Q35: =Q33 / (Q33 + S33) -> 0.10344828

Sheet rodada 14
B1: Parafusos | E1: Arruelas | H1: Alfinete | K1: Porta Agulhas | N1: Allis | Q1: Anatomica
A2: filename | B2: VP | C2: FP | D2: FN | E2: VP | F2: FP | G2: FN | H2: VP | I2: FP | J2: FN | K2: VP | L2: FP | M2: FN | N2: VP | O2: FP | P2: FN | Q2: VP | R2: FP | S2: FN
A3: Min_Chaos_Rodada_14_Imagem 01 | B3: 0 | C3: 0 | D3: 5 | E3: 0 | F3: 0 | G3: 5 | H3: 1 | I3: 0 | J3: 0 | K3: 2 | L3: 1 | M3: 0 | N3: 0 | O3: 0 | P3: 1 | Q3: 1 | R3: 0 | S3: 0
A4: Min_Chaos_Rodada_14_Imagem 02 | B4: 0 | C4: 0 | D4: 4 | E4: 0 | F4: 0 | G4: 5 | H4: 1 | I4: 0 | J4: 0 | K4: 2 | L4: 0 | M4: 0 | N4: 0 | O4: 0 | P4: 1 | Q4: 1 | R4: 0 | S4: 0
A5: Min_Chaos_Rodada_14_Imagem 03 | B5: 1 | C5: 0 | D5: 2 | E5: 1 | F5: 0 | G5: 4 | H5: 1 | I5: 0 | J5: 0 | K5: 2 | L5: 0 | M5: 0 | N5: 0 | O5: 0 | P5: 1 | Q5: 1 | R5: 0 | S5: 0
A6: Min_Chaos_Rodada_14_Imagem 04 | B6: 1 | C6: 0 | D6: 1 | E6: 1 | F6: 0 | G6: 4 | H6: 1 | I6: 0 | J6: 0 | K6: 2 | L6: 0 | M6: 0 | N6: 0 | O6: 0 | P6: 1 | Q6: 1 | R6: 0 | S6: 0
A7: Min_Chaos_Rodada_14_Imagem 05 | B7: 0 | C7: 0 | D7: 1 | E7: 1 | F7: 0 | G7: 4 | H7: 1 | I7: 0 | J7: 0 | K7: 2 | L7: 0 | M7: 0 | N7: 0 | O7: 0 | P7: 1 | Q7: 1 | R7: 0 | S7: 0
A8: Min_Chaos_Rodada_14_Imagem 06 | B8: 0 | C8: 0 | D8: 0 | E8: 2 | F8: 0 | G8: 3 | H8: 1 | I8: 0 | J8: 0 | K8: 2 | L8: 0 | M8: 0 | N8: 0 | O8: 0 | P8: 1 | Q8: 1 | R8: 0 | S8: 0
A9: Min_Chaos_Rodada_14_Imagem 07 | B9: 0 | C9: 0 | D9: 0 | E9: 2 | F9: 0 | G9: 2 | H9: 1 | I9: 0 | J9: 0 | K9: 2 | L9: 0 | M9: 0 | N9: 0 | O9: 0 | P9: 1 | Q9: 1 | R9: 0 | S9: 0
A10: Min_Chaos_Rodada_14_Imagem 08 | B10: 0 | C10: 0 | D10: 0 | E10: 0 | F10: 0 | G10: 3 | H10: 1 | I10: 0 | J10: 0 | K10: 2 | L10: 0 | M10: 0 | N10: 0 | O10: 0 | P10: 1 | Q10: 1 | R10: 0 | S10: 0
A11: Min_Chaos_Rodada_14_Imagem 09 | B11: 0 | C11: 0 | D11: 0 | E11: 0 | F11: 0 | G11: 2 | H11: 1 | I11: 0 | J11: 0 | K11: 2 | L11: 0 | M11: 0 | N11: 0 | O11: 0 | P11: 1 | Q11: 1 | R11: 0 | S11: 0
A12: Min_Chaos_Rodada_14_Imagem 10 | B12: 0 | C12: 0 | D12: 0 | E12: 0 | F12: 0 | G12: 1 | H12: 1 | I12: 0 | J12: 0 | K12: 2 | L12: 0 | M12: 0 | N12: 0 | O12: 0 | P12: 1 | Q12: 1 | R12: 0 | S12: 0
A13: Min_Chaos_Rodada_14_Imagem 11 | B13: 0 | C13: 0 | D13: 0 | E13: 0 | F13: 0 | G13: 0 | H13: 1 | I13: 0 | J13: 0 | K13: 2 | L13: 0 | M13: 0 | N13: 0 | O13: 0 | P13: 1 | Q13: 1 | R13: 0 | S13: 0
A14: Min_Chaos_Rodada_14_Imagem 12 | B14: 0 | C14: 0 | D14: 0 | E14: 0 | F14: 0 | G14: 0 | H14: 0 | I14: 0 | J14: 0 | K14: 2 | L14: 0 | M14: 0 | N14: 0 | O14: 0 | P14: 1 | Q14: 1 | R14: 0 | S14: 0
... A33: Min_Chaos_Rodada_14_Imagem 31 | B33: 1 | C33: 0 | D33: 4 | E33: 0 | F33: 0 | G33: 5 | H33: 0 | I33: 0 | J33: 1 | K33: 1 | L33: 0 | M33: 1 | N33: 0 | O33: 0 | P33: 1 | Q33: 1 | R33: 0 | S33: 0
A34: Total: | B34: =SUM(B3:B33) -> 3 | C34: =SUM(C3:C33) -> 0 | D34: =SUM(D3:D33) -> 27 | E34: =SUM(E3:E33) -> 12 | F34: =SUM(F3:F33) -> 0 | G34: =SUM(G3:G33) -> 68 | H34: =SUM(H3:H33) -> 18 | I34: =SUM(I3:I33) -> 0 | ... S34: =SUM(S3:S33) -> 1
A35: Precisão: | B35: =B34 / (B34 + C34) -> 1 | E35: =E34 / (E34 + F34) -> 1 | H35: =H34 / (H34 + I34) -> 1 | K35: =K34 / (K34 + L34) -> 0.90697674 | N35: =N34 / (N34 + O34) -> 1 | Q35: =Q34 / (Q34 + R34) -> 1
A36: Acurácia | B36: =B34 / (B34 + D34) -> 0.1 | E36: =E34 / (E34 + G34) -> 0.15 | H36: =H34 / (H34 + J34) -> 0.81818182 | K36: =K34 / (K34 + M34) -> 0.78 | N36: =N34 / (N34 + P34) -> 0.035714286 | Q36: =Q34 / (Q34 + S34) -> 0.96666667

Sheet rodada 15
B1: Parafusos | E1: Arruelas | H1: Alfinete | K1: Porta Agulhas | N1: Allis | Q1: Anatomica
A2: filename | B2: VP | C2: FP | D2: FN | E2: VP | F2: FP | G2: FN | H2: VP | I2: FP | J2: FN | K2: VP | L2: FP | M2: FN | N2: VP | O2: FP | P2: FN | Q2: VP | R2: FP | S2: FN
A3: Min_Chaos_Rodada_15_Imagem 01 | B3: 1 | C3: 0 | D3: 4 | E3: 0 | F3: 0 | G3: 5 | H3: 0 | I3: 0 | J3: 1 | K3: 1 | L3: 0 | M3: 1 | N3: 0 | O3: 0 | P3: 1 | Q3: 1 | R3: 0 | S3: 0
A4: Min_Chaos_Rodada_15_Imagem 02 | B4: 1 | C4: 0 | D4: 3 | E4: 0 | F4: 0 | G4: 5 | H4: 0 | I4: 0 | J4: 1 | K4: 2 | L4: 0 | M4: 0 | N4: 0 | O4: 0 | P4: 1 | Q4: 1 | R4: 0 | S4: 0
A5: Min_Chaos_Rodada_15_Imagem 03 | B5: 2 | C5: 0 | D5: 1 | E5: 0 | F5: 0 | G5: 5 | H5: 0 | I5: 0 | J5: 1 | K5: 1 | L5: 0 | M5: 1 | N5: 0 | O5: 0 | P5: 1 | Q5: 1 | R5: 0 | S5: 0
A6: Min_Chaos_Rodada_15_Imagem 04 | B6: 1 | C6: 0 | D6: 1 | E6: 0 | F6: 0 | G6: 5 | H6: 0 | I6: 0 | J6: 1 | K6: 1 | L6: 0 | M6: 1 | N6: 0 | O6: 0 | P6: 1 | Q6: 1 | R6: 0 | S6: 0
A7: Min_Chaos_Rodada_15_Imagem 05 | B7: 0 | C7: 0 | D7: 1 | E7: 1 | F7: 0 | G7: 4 | H7: 1 | I7: 0 | J7: 0 | K7: 1 | L7: 0 | M7: 1 | N7: 0 | O7: 0 | P7: 1 | Q7: 1 | R7: 0 | S7: 0
A8: Min_Chaos_Rodada_15_Imagem 06 | B8: 0 | C8: 0 | D8: 0 | E8: 1 | F8: 0 | G8: 4 | H8: 1 | I8: 0 | J8: 0 | K8: 1 | L8: 0 | M8: 1 | N8: 0 | O8: 0 | P8: 1 | Q8: 1 | R8: 0 | S8: 0
A9: Min_Chaos_Rodada_15_Imagem 07 | B9: 0 | C9: 0 | D9: 0 | E9: 0 | F9: 0 | G9: 4 | H9: 1 | I9: 0 | J9: 0 | K9: 1 | L9: 0 | M9: 1 | N9: 0 | O9: 0 | P9: 1 | Q9: 1 | R9: 0 | S9: 0
A10: Min_Chaos_Rodada_15_Imagem 08 | B10: 0 | C10: 0 | D10: 0 | E10: 0 | F10: 0 | G10: 3 | H10: 1 | I10: 0 | J10: 0 | K10: 1 | L10: 0 | M10: 1 | N10: 0 | O10: 0 | P10: 1 | Q10: 1 | R10: 0 | S10: 0
A11: Min_Chaos_Rodada_15_Imagem 09 | B11: 0 | C11: 0 | D11: 0 | E11: 0 | F11: 0 | G11: 2 | H11: 1 | I11: 0 | J11: 0 | K11: 1 | L11: 0 | M11: 1 | N11: 0 | O11: 0 | P11: 1 | Q11: 1 | R11: 0 | S11: 0
A12: Min_Chaos_Rodada_15_Imagem 10 | B12: 0 | C12: 0 | D12: 0 | E12: 0 | F12: 0 | G12: 1 | H12: 1 | I12: 0 | J12: 0 | K12: 1 | L12: 0 | M12: 1 | N12: 0 | O12: 0 | P12: 1 | Q12: 1 | R12: 0 | S12: 0
A13: Min_Chaos_Rodada_15_Imagem 11 | B13: 0 | C13: 0 | D13: 0 | E13: 0 | F13: 0 | G13: 0 | H13: 1 | I13: 0 | J13: 0 | K13: 1 | L13: 0 | M13: 1 | N13: 0 | O13: 0 | P13: 1 | Q13: 1 | R13: 0 | S13: 0
A14: Min_Chaos_Rodada_15_Imagem 12 | B14: 0 | C14: 0 | D14: 0 | E14: 0 | F14: 0 | G14: 0 | H14: 0 | I14: 0 | J14: 0 | K14: 2 | L14: 0 | M14: 0 | N14: 0 | O14: 0 | P14: 1 | Q14: 1 | R14: 0 | S14: 0
... A33: Min_Chaos_Rodada_15_Imagem 31 | B33: 1 | C33: 0 | D33: 4 | E33: 0 | F33: 0 | G33: 5 | H33: 0 | I33: 0 | J33: 1 | K33: 1 | L33: 0 | M33: 1 | N33: 1 | O33: 0 | P33: 0 | Q33: 0 | R33: 0 | S33: 1
A34: Total: | B34: =SUM(B3:B33) -> 10 | C34: =SUM(C3:C33) -> 0 | D34: =SUM(D3:D33) -> 20 | E34: =SUM(E3:E33) -> 4 | F34: =SUM(F3:F33) -> 0 | G34: =SUM(G3:G33) -> 76 | H34: =SUM(H3:H33) -> 7 | I34: =SUM(I3:I33) -> 0 | ... S34: =SUM(S3:S33) -> 16
A35: Precisão: | B35: =B34 / (B34 + C34) -> 1 | E35: =E34 / (E34 + F34) -> 1 | H35: =H34 / (H34 + I34) -> 1 | K35: =K34 / (K34 + L34) -> 0.925 | N35: =N34 / (N34 + O34) -> 1 | Q35: =Q34 / (Q34 + R34) -> 1
A36: Acurácia | B36: =B34 / (B34 + D34) -> 0.33333333 | E36: =E34 / (E34 + G34) -> 0.05 | H36: =H34 / (H34 + J34) -> 0.31818182 | K36: =K34 / (K34 + M34) -> 0.74 | N36: =N34 / (N34 + P34) -> 0.46428571 | Q36: =Q34 / (Q34 + S34) -> 0.46666667

Sheet rodada 16
B1: Parafusos | E1: Arruelas | H1: Alfinete | K1: Porta Agulhas | N1: Allis | Q1: Anatomica
A2: filename | B2: VP | C2: FP | D2: FN | E2: VP | F2: FP | G2: FN | H2: VP | I2: FP | J2: FN | K2: VP | L2: FP | M2: FN | N2: VP | O2: FP | P2: FN | Q2: VP | R2: FP | S2: FN
A3: Min_Chaos_Rodada_16_Imagem 01 | B3: 1 | C3: 0 | D3: 4 | E3: 0 | F3: 0 | G3: 5 | H3: 0 | I3: 0 | J3: 1 | K3: 1 | L3: 0 | M3: 1 | N3: 0 | O3: 0 | P3: 1 | Q3: 0 | R3: 0 | S3: 1
A4: Min_Chaos_Rodada_16_Imagem 02 | B4: 0 | C4: 0 | D4: 4 | E4: 0 | F4: 0 | G4: 5 | H4: 1 | I4: 0 | J4: 0 | K4: 1 | L4: 0 | M4: 1 | N4: 0 | O4: 0 | P4: 1 | Q4: 0 | R4: 0 | S4: 1
A5: Min_Chaos_Rodada_16_Imagem 03 | B5: 0 | C5: 0 | D5: 3 | E5: 0 | F5: 0 | G5: 5 | H5: 1 | I5: 0 | J5: 0 | K5: 1 | L5: 0 | M5: 1 | N5: 0 | O5: 0 | P5: 1 | Q5: 0 | R5: 0 | S5: 1
A6: Min_Chaos_Rodada_16_Imagem 04 | B6: 1 | C6: 0 | D6: 1 | E6: 0 | F6: 0 | G6: 5 | H6: 1 | I6: 0 | J6: 0 | K6: 1 | L6: 0 | M6: 1 | N6: 0 | O6: 0 | P6: 1 | Q6: 0 | R6: 0 | S6: 1
A7: Min_Chaos_Rodada_16_Imagem 05 | B7: 1 | C7: 0 | D7: 0 | E7: 0 | F7: 0 | G7: 5 | H7: 1 | I7: 0 | J7: 0 | K7: 1 | L7: 0 | M7: 1 | N7: 0 | O7: 0 | P7: 1 | Q7: 0 | R7: 0 | S7: 1
A8: Min_Chaos_Rodada_16_Imagem 06 | B8: 0 | C8: 0 | D8: 0 | E8: 0 | F8: 0 | G8: 5 | H8: 1 | I8: 0 | J8: 0 | K8: 1 | L8: 0 | M8: 1 | N8: 0 | O8: 0 | P8: 1 | Q8: 0 | R8: 0 | S8: 1
A9: Min_Chaos_Rodada_16_Imagem 07 | B9: 0 | C9: 0 | D9: 0 | E9: 0 | F9: 0 | G9: 4 | H9: 1 | I9: 0 | J9: 0 | K9: 1 | L9: 0 | M9: 1 | N9: 0 | O9: 0 | P9: 1 | Q9: 0 | R9: 0 | S9: 1
A10: Min_Chaos_Rodada_16_Imagem 08 | B10: 0 | C10: 0 | D10: 0 | E10: 2 | F10: 0 | G10: 1 | H10: 1 | I10: 0 | J10: 0 | K10: 1 | L10: 0 | M10: 1 | N10: 0 | O10: 0 | P10: 1 | Q10: 0 | R10: 0 | S10: 1
A11: Min_Chaos_Rodada_16_Imagem 09 | B11: 0 | C11: 0 | D11: 0 | E11: 1 | F11: 0 | G11: 1 | H11: 1 | I11: 0 | J11: 0 | K11: 1 | L11: 0 | M11: 1 | N11: 0 | O11: 0 | P11: 1 | Q11: 0 | R11: 0 | S11: 1
A12: Min_Chaos_Rodada_16_Imagem 10 | B12: 0 | C12: 0 | D12: 0 | E12: 1 | F12: 0 | G12: 0 | H12: 1 | I12: 0 | J12: 0 | K12: 1 | L12: 0 | M12: 1 | N12: 0 | O12: 0 | P12: 1 | Q12: 0 | R12: 0 | S12: 1
A13: Min_Chaos_Rodada_16_Imagem 11 | B13: 0 | C13: 0 | D13: 0 | E13: 0 | F13: 0 | G13: 0 | H13: 1 | I13: 0 | J13: 0 | K13: 2 | L13: 0 | M13: 0 | N13: 0 | O13: 0 | P13: 1 | Q13: 0 | R13: 0 | S13: 1
A14: Min_Chaos_Rodada_16_Imagem 12 | B14: 0 | C14: 0 | D14: 0 | E14: 0 | F14: 0 | G14: 0 | H14: 0 | I14: 0 | J14: 0 | K14: 2 | L14: 0 | M14: 0 | N14: 1 | O14: 0 | P14: 0 | Q14: 0 | R14: 0 | S14: 1
... A33: Min_Chaos_Rodada_16_Imagem 31 | B33: 0 | C33: 0 | D33: 5 | E33: 0 | F33: 0 | G33: 5 | H33: 0 | I33: 0 | J33: 1 | K33: 0 | L33: 0 | M33: 2 | N33: 1 | O33: 0 | P33: 0 | Q33: 0 | R33: 0 | S33: 1
A34: Total: | B34: =SUM(B3:B33) -> 7 | C34: =SUM(C3:C33) -> 0 | D34: =SUM(D3:D33) -> 23 | E34: =SUM(E3:E33) -> 7 | F34: =SUM(F3:F33) -> 0 | G34: =SUM(G3:G33) -> 73 | H34: =SUM(H3:H33) -> 13 | I34: =SUM(I3:I33) -> 0 | ... S34: =SUM(S3:S33) -> 30
A35: Precisão: | B35: =B34 / (B34 + C34) -> 1 | E35: =E34 / (E34 + F34) -> 1 | H35: =H34 / (H34 + I34) -> 1 | K35: =K34 / (K34 + L34) -> 0.83333333 | N35: =N34 / (N34 + O34) -> 1 | Q35: =Q34 / (Q34 + R34) -> #DIV/0!
A36: Acurácia | B36: =B34 / (B34 + D34) -> 0.23333333 | E36: =E34 / (E34 + G34) -> 0.0875 | H36: =H34 / (H34 + J34) -> 0.59090909 | K36: =K34 / (K34 + M34) -> 0.6 | N36: =N34 / (N34 + P34) -> 0.32142857 | Q36: =Q34 / (Q34 + S34) -> 0

Sheet rodada 17
B1: Parafusos | E1: Arruelas | H1: Alfinete | K1: Porta Agulhas | N1: Allis | Q1: Anatomica
A2: filename | B2: VP | C2: FP | D2: FN | E2: VP | F2: FP | G2: FN | H2: VP | I2: FP | J2: FN | K2: VP | L2: FP | M2: FN | N2: VP | O2: FP | P2: FN | Q2: VP | R2: FP | S2: FN
A3: Min_Chaos_Rodada_17_Imagem 01 | B3: 1 | C3: 0 | D3: 4 | E3: 1 | F3: 0 | G3: 4 | H3: 0 | I3: 0 | J3: 1 | K3: 1 | L3: 0 | M3: 1 | N3: 1 | O3: 0 | P3: 0 | Q3: 0 | R3: 0 | S3: 1
A4: Min_Chaos_Rodada_17_Imagem 02 | B4: 0 | C4: 0 | D4: 4 | E4: 0 | F4: 0 | G4: 5 | H4: 0 | I4: 0 | J4: 1 | K4: 1 | L4: 0 | M4: 1 | N4: 1 | O4: 0 | P4: 0 | Q4: 0 | R4: 0 | S4: 1
A5: Min_Chaos_Rodada_17_Imagem 03 | B5: 0 | C5: 0 | D5: 3 | E5: 0 | F5: 0 | G5: 5 | H5: 0 | I5: 0 | J5: 1 | K5: 2 | L5: 0 | M5: 0 | N5: 1 | O5: 0 | P5: 0 | Q5: 0 | R5: 0 | S5: 1
A6: Min_Chaos_Rodada_17_Imagem 04 | B6: 1 | C6: 0 | D6: 1 | E6: 0 | F6: 0 | G6: 5 | H6: 0 | I6: 0 | J6: 1 | K6: 2 | L6: 0 | M6: 0 | N6: 1 | O6: 0 | P6: 0 | Q6: 0 | R6: 0 | S6: 1
A7: Min_Chaos_Rodada_17_Imagem 05 | B7: 1 | C7: 0 | D7: 0 | E7: 0 | F7: 0 | G7: 5 | H7: 0 | I7: 0 | J7: 1 | K7: 2 | L7: 0 | M7: 0 | N7: 1 | O7: 0 | P7: 0 | Q7: 0 | R7: 0 | S7: 1
A8: Min_Chaos_Rodada_17_Imagem 06 | B8: 0 | C8: 0 | D8: 0 | E8: 0 | F8: 0 | G8: 5 | H8: 1 | I8: 0 | J8: 0 | K8: 1 | L8: 0 | M8: 1 | N8: 1 | O8: 0 | P8: 0 | Q8: 0 | R8: 0 | S8: 1
A9: Min_Chaos_Rodada_17_Imagem 07 | B9: 0 | C9: 0 | D9: 0 | E9: 1 | F9: 0 | G9: 3 | H9: 1 | I9: 0 | J9: 0 | K9: 0 | L9: 0 | M9: 2 | N9: 1 | O9: 0 | P9: 0 | Q9: 0 | R9: 0 | S9: 1
A10: Min_Chaos_Rodada_17_Imagem 08 | B10: 0 | C10: 0 | D10: 0 | E10: 0 | F10: 0 | G10: 3 | H10: 1 | I10: 0 | J10: 0 | K10: 0 | L10: 0 | M10: 2 | N10: 1 | O10: 0 | P10: 0 | Q10: 0 | R10: 0 | S10: 1
A11: Min_Chaos_Rodada_17_Imagem 09 | B11: 0 | C11: 0 | D11: 0 | E11: 0 | F11: 0 | G11: 2 | H11: 0 | I11: 0 | J11: 1 | K11: 1 | L11: 0 | M11: 1 | N11: 1 | O11: 0 | P11: 0 | Q11: 0 | R11: 0 | S11: 1
A12: Min_Chaos_Rodada_17_Imagem 10 | B12: 0 | C12: 0 | D12: 0 | E12: 1 | F12: 0 | G12: 0 | H12: 0 | I12: 0 | J12: 1 | K12: 1 | L12: 0 | M12: 1 | N12: 1 | O12: 0 | P12: 0 | Q12: 0 | R12: 0 | S12: 1
A13: Min_Chaos_Rodada_17_Imagem 11 | B13: 0 | C13: 0 | D13: 0 | E13: 0 | F13: 0 | G13: 0 | H13: 0 | I13: 0 | J13: 1 | K13: 1 | L13: 0 | M13: 1 | N13: 1 | O13: 0 | P13: 0 | Q13: 0 | R13: 0 | S13: 1
A14: Min_Chaos_Rodada_17_Imagem 12 | B14: 0 | C14: 0 | D14: 0 | E14: 0 | F14: 0 | G14: 0 | H14: 0 | I14: 0 | J14: 0 | K14: 2 | L14: 1 | M14: 0 | N14: 0 | O14: 0 | P14: 1 | Q14: 0 | R14: 0 | S14: 1
... A33: Min_Chaos_Rodada_17_Imagem 31 | B33: 2 | C33: 0 | D33: 3 | E33: 0 | F33: 0 | G33: 5 | H33: 0 | I33: 0 | J33: 1 | K33: 1 | L33: 0 | M33: 1 | N33: 0 | O33: 0 | P33: 1 | Q33: 0 | R33: 1 | S33: 1
A34: Total: | B34: =SUM(B3:B33) -> 8 | C34: =SUM(C3:C33) -> 0 | D34: =SUM(D3:D33) -> 22 | E34: =SUM(E3:E33) -> 5 | F34: =SUM(F3:F33) -> 0 | G34: =SUM(G3:G33) -> 75 | H34: =SUM(H3:H33) -> 8 | I34: =SUM(I3:I33) -> 0 | ... S34: =SUM(S3:S33) -> 30
A35: Precisão: | B35: =B34 / (B34 + C34) -> 1 | E35: =E34 / (E34 + F34) -> 1 | H35: =H34 / (H34 + I34) -> 1 | K35: =K34 / (K34 + L34) -> 0.82857143 | N35: =N34 / (N34 + O34) -> 1 | Q35: =Q34 / (Q34 + R34) -> 0
A36: Acurácia | B36: =B34 / (B34 + D34) -> 0.26666667 | E36: =E34 / (E34 + G34) -> 0.0625 | H36: =H34 / (H34 + J34) -> 0.36363636 | K36: =K34 / (K34 + M34) -> 0.58 | N36: =N34 / (N34 + P34) -> 0.42857143 | Q36: =Q34 / (Q34 + S34) -> 0

Sheet rodada 18
B1: Parafusos | E1: Arruelas | H1: Alfinete | K1: Porta Agulhas | N1: Allis | Q1: Anatomica
A2: filename | B2: VP | C2: FP | D2: FN | E2: VP | F2: FP | G2: FN | H2: VP | I2: FP | J2: FN | K2: VP | L2: FP | M2: FN | N2: VP | O2: FP | P2: FN | Q2: VP | R2: FP | S2: FN
A3: Min_Chaos_Rodada_18_Imagem 01 | B3: 2 | C3: 0 | D3: 3 | E3: 0 | F3: 0 | G3: 5 | H3: 0 | I3: 0 | J3: 1 | K3: 2 | L3: 0 | M3: 0 | N3: 0 | O3: 0 | P3: 1 | Q3: 0 | R3: 0 | S3: 1
A4: Min_Chaos_Rodada_18_Imagem 02 | B4: 2 | C4: 0 | D4: 2 | E4: 0 | F4: 0 | G4: 5 | H4: 0 | I4: 0 | J4: 1 | K4: 1 | L4: 0 | M4: 1 | N4: 0 | O4: 0 | P4: 1 | Q4: 0 | R4: 1 | S4: 1
A5: Min_Chaos_Rodada_18_Imagem 03 | B5: 1 | C5: 0 | D5: 2 | E5: 0 | F5: 0 | G5: 5 | H5: 0 | I5: 0 | J5: 1 | K5: 1 | L5: 0 | M5: 1 | N5: 0 | O5: 0 | P5: 1 | Q5: 0 | R5: 1 | S5: 1
A6: Min_Chaos_Rodada_18_Imagem 04 | B6: 1 | C6: 0 | D6: 1 | E6: 0 | F6: 0 | G6: 5 | H6: 1 | I6: 0 | J6: 0 | K6: 1 | L6: 0 | M6: 1 | N6: 0 | O6: 0 | P6: 1 | Q6: 0 | R6: 1 | S6: 1
A7: Min_Chaos_Rodada_18_Imagem 05 | B7: 1 | C7: 0 | D7: 0 | E7: 0 | F7: 0 | G7: 5 | H7: 0 | I7: 0 | J7: 1 | K7: 1 | L7: 0 | M7: 1 | N7: 0 | O7: 0 | P7: 1 | Q7: 0 | R7: 1 | S7: 1
A8: Min_Chaos_Rodada_18_Imagem 06 | B8: 0 | C8: 0 | D8: 0 | E8: 0 | F8: 0 | G8: 5 | H8: 1 | I8: 0 | J8: 0 | K8: 1 | L8: 0 | M8: 1 | N8: 0 | O8: 0 | P8: 1 | Q8: 0 | R8: 1 | S8: 1
A9: Min_Chaos_Rodada_18_Imagem 07 | B9: 0 | C9: 0 | D9: 0 | E9: 0 | F9: 0 | G9: 4 | H9: 1 | I9: 0 | J9: 0 | K9: 1 | L9: 1 | M9: 1 | N9: 0 | O9: 0 | P9: 1 | Q9: 0 | R9: 1 | S9: 1
A10: Min_Chaos_Rodada_18_Imagem 08 | B10: 0 | C10: 0 | D10: 0 | E10: 0 | F10: 0 | G10: 3 | H10: 1 | I10: 0 | J10: 0 | K10: 1 | L10: 0 | M10: 1 | N10: 0 | O10: 0 | P10: 1 | Q10: 0 | R10: 1 | S10: 1
A11: Min_Chaos_Rodada_18_Imagem 09 | B11: 0 | C11: 0 | D11: 0 | E11: 2 | F11: 0 | G11: 0 | H11: 1 | I11: 0 | J11: 0 | K11: 1 | L11: 0 | M11: 1 | N11: 0 | O11: 0 | P11: 1 | Q11: 0 | R11: 1 | S11: 1
A12: Min_Chaos_Rodada_18_Imagem 10 | B12: 0 | C12: 0 | D12: 0 | E12: 0 | F12: 0 | G12: 1 | H12: 1 | I12: 0 | J12: 0 | K12: 1 | L12: 0 | M12: 1 | N12: 0 | O12: 0 | P12: 1 | Q12: 0 | R12: 1 | S12: 1
